Workbook

Sheet Мартыновская
A1: Реактансы ПС 35/6кВ СР-1
A2: СР | B2: Наименование ПС 35/6кВ | C2: Тип ПС | D2: №Ф-35кВ | E2: Режим | F2: Головная ПС | G2: Реактансы на с.ш.35кВ ПС 110/35/6кВ | I2: Длина ВЛ-35кВ | P2: Хвл-35кВ | R2: Реактансы на 110 ПС Мартыновская | T2: Токи на с.ш.35кВ ПС 35/6кВ до трансф. | V2: № тр-ра | W2: Тип | X2: S | Y2: Груп Соед | Z2: U ВН | AA2: U HН | AB2: Uкз | AC2: Iвн/Iнн | AD2: РПН | AE2: Хтмак | AF2: Реактансы на с.ш.35кВ ПС 35/6кВ | AH2: Реактансы на с.ш.6кВ ПС 35/6кВ | AJ2: Токи на с.ш.6кВ ПС 35/6кВ после трансф., приведенные к стороне 35кВ | AL2: Кч=1.2 | AM2: Кч=1.5 | AN2: Токи на с.ш.6кВ ПС 35/6кВ после трансф., приведенные к стороне 6,3кВ
G3: Хсмакc | H3: Хсмин | I3: АС-95 | J3: АС-120 | K3: АС-150 | L3: АПвП 300 | M3: АС-150 | N3: АС-185 | O3: АС-500 | R3: Хмакс | S3: Хмин | T3: Iмакс | U3: Iмин | AF3: Хмакс | AG3: Хмин | AH3: Хмакс | AI3: Хмин | AJ3: Iмакс | AK3: Iмин | AN3: Iмакс | AO3: Iмин
G4: Ом | H4: Ом | I4: км | J4: км | K4: км | L4: км | M4: км | N4: км | O4: км | P4: Ом | Q4: Ом | R4: Ом | S4: Ом | T4: А | U4: А | X4: МВА | Z4: кВ | AA4: кВ | AB4: % | AC4: А | AD4: % | AE4: Ом | AF4: Ом | AG4: Ом | AH4: Ом | AI4: Ом | AJ4: А | AK4: А | AL4: А | AM4: А | AN4: А | AO4: А
A5: 1 | B5: ДНС-2В | C5: К-47 | D5: 5.6 | E5: Н | F5: Кирьяновская | G5: 2.755 | H5: 7.073 | J5: 0.83 | K5: 5.13 | P5: =0.314*I5+0.249*J5+0.204*M5+0.159*N5+0.06*O5 -> 0.20667 | Q5: =0.4*SUM(I5:O5) -> 2.384 | R5: =SQRT(POWER(P5,2)+POWER(Q5+G5,2)) -> 5.143154 | S5: =SQRT(POWER(P5,2)+POWER(Q5+H5,2)) -> 9.459258 | T5: =115000/1.73/SQRT(POWER((R5+Q5),2)+P5*P5) -> 8827.8978 | U5: =115000/2/SQRT(P5*P5+POWER((S5+Q5),2)) -> 4854.3439 | V5: 1 | W5: TМН-4000/35 | X5: 4 | Y5: 11 | Z5: 35 | AA5: 6.3 | AB5: 7.67 | AC5: 66/366 | AD5: 9 | AE5: =AB5/100*Z5*Z5/X5 -> 23.489375 | AF5: =SQRT(POWER(P5,2)+POWER(Q5+AE5+G5,2)) -> 28.629121 | AG5: =SQRT(POWER(P5,2)+POWER(Q5+AE5+H5,2)) -> 32.947023 | AH5: =SQRT(POWER((AE5+Q5+G5),2)+POWER(P5,2))*POWER(6.3/Z5,2) -> 0.92758352 | AI5: =SQRT(POWER((H5+Q5+AE5),2)+POWER(P5,2))*POWER(6.3/Z5,2) -> 1.0674836 | AJ5: =37000/1.73/SQRT(POWER((G5+Q5+AE5),2)+P5*P5) -> 747.04645 | AK5: =37000/2/SQRT(POWER((H5+Q5+AE5),2)+P5*P5) -> 561.50748 | AL5: =AK5/1.2 -> 467.9229 | AM5: =AK5/1.5 -> 374.33832 | AN5: =6300/(1.73*AH5) -> 3925.9198 | AO5: =SUM(6300/(2*AI5)) -> 2950.8651
A6: 1 | D6: 5.6 | E6: Н | F6: Кирьяновская | G6: 2.755 | H6: 7.073 | J6: 0.83 | K6: 5.13 | P6: =0.314*I6+0.249*J6+0.204*M6+0.159*N6+0.06*O6 -> 0.20667 | Q6: =0.4*SUM(I6:O6) -> 2.384 | R6: =SQRT(POWER(P6,2)+POWER(Q6+G6,2)) -> 5.143154 | S6: =SQRT(POWER(P6,2)+POWER(Q6+H6,2)) -> 9.459258 | T6: =115000/1.73/SQRT(POWER((R6+Q6),2)+P6*P6) -> 8827.8978 | U6: =115000/2/SQRT(P6*P6+POWER((S6+Q6),2)) -> 4854.3439 | V6: 2 | W6: TМН-4000/35 | X6: 4 | Y6: 11 | Z6: 35 | AA6: 6.3 | AB6: 7.6 | AC6: 66/366 | AD6: 12 | AE6: =AB6/100*Z6*Z6/X6 -> 23.275 | AF6: =SQRT(POWER(P6,2)+POWER(Q6+AE6+G6,2)) -> 28.414752 | AG6: =SQRT(POWER(P6,2)+POWER(Q6+AE6+H6,2)) -> 32.732652 | AH6: =SQRT(POWER((AE6+Q6+G6),2)+POWER(P6,2))*POWER(6.3/Z6,2) -> 0.92063795 | AI6: =SQRT(POWER((H6+Q6+AE6),2)+POWER(P6,2))*POWER(6.3/Z6,2) -> 1.0605379 | AJ6: =37000/1.73/SQRT(POWER((G6+Q6+AE6),2)+P6*P6) -> 752.68239 | AK6: =37000/2/SQRT(POWER((H6+Q6+AE6),2)+P6*P6) -> 565.18487 | AL6: =AK6/1.2 -> 470.98739 | AM6: =AK6/1.5 -> 376.78991 | AN6: =6300/(1.73*AH6) -> 3955.5381 | AO6: =SUM(6300/(2*AI6)) -> 2970.1908
A7: 1 | B7: КНС-4В | C7: К-47 | D7: 5.6 | E7: Н | F7: Кирьяновская | G7: 2.55 | H7: 5.42 | J7: 0.35 | P7: =0.314*I7+0.249*J7+0.195*M7+0.159*N7+0.06*O7 -> 0.08715 | Q7: =0.4*SUM(I7:O7) -> 0.14 | R7: =SQRT(POWER(P7,2)+POWER(Q7+G7,2)) -> 2.6914114 | S7: =SQRT(POWER(P7,2)+POWER(Q7+H7,2)) -> 5.560683 | T7: =37000/1.73/SQRT(POWER((G7+Q7),2)+P7*P7) -> 7946.4936 | U7: =37000/2/SQRT(P7*P7+POWER((H7+Q7),2)) -> 3326.9295 | V7: 1 | W7: ТМН 6300/35 | X7: 6.3 | Y7: 11 | Z7: 35 | AA7: 6.3 | AB7: 7.82 | AC7: 103,9/577,3 | AE7: =AB7/100*Z7*Z7/X7 -> 15.205556 | AF7: =SQRT(POWER(P7,2)+POWER(Q7+AE7+G7,2)) -> 17.895768 | AG7: =SQRT(POWER(P7,2)+POWER(Q7+AE7+H7,2)) -> 20.765738 | AH7: =SQRT(POWER((AE7+Q7+G7),2)+POWER(P7,2))*POWER(6.3/Z7,2) -> 0.57982288 | AI7: =SQRT(POWER((H7+Q7+AE7),2)+POWER(P7,2))*POWER(6.3/Z7,2) -> 0.67280993 | AJ7: =37000/1.73/SQRT(POWER((G7+Q7+AE7),2)+P7*P7) -> 1195.1029 | AK7: =37000/2/SQRT(POWER((H7+Q7+AE7),2)+P7*P7) -> 890.89054 | AL7: =AK7/1.2 -> 742.40879 | AM7: =AK7/1.5 -> 593.92703 | AN7: =6300/(1.73*AH7) -> 6280.5706 | AO7: =SUM(6300/(2*AI7)) -> 4681.8572
A8: 1 | D8: 5.6 | E8: Н | F8: Кирьяновская | G8: 2.55 | H8: 5.42 | J8: 0.35 | P8: =0.314*I8+0.249*J8+0.195*M8+0.159*N8+0.06*O8 -> 0.08715 | Q8: =0.4*SUM(I8:O8) -> 0.14 | R8: =SQRT(POWER(P8,2)+POWER(Q8+G8,2)) -> 2.6914114 | S8: =SQRT(POWER(P8,2)+POWER(Q8+H8,2)) -> 5.560683 | T8: =37000/1.73/SQRT(POWER((G8+Q8),2)+P8*P8) -> 7946.4936 | U8: =37000/2/SQRT(P8*P8+POWER((H8+Q8),2)) -> 3326.9295 | V8: 2 | W8: ТМН 6300/35 | X8: 6.3 | Y8: 11 | Z8: 35 | AA8: 6.3 | AB8: 7.94 | AC8: 103,9/577,3 | AE8: =AB8/100*Z8*Z8/X8 -> 15.438889 | AF8: =SQRT(POWER(P8,2)+POWER(Q8+AE8+G8,2)) -> 18.129098 | AG8: =SQRT(POWER(P8,2)+POWER(Q8+AE8+H8,2)) -> 20.99907 | AH8: =SQRT(POWER((AE8+Q8+G8),2)+POWER(P8,2))*POWER(6.3/Z8,2) -> 0.58738279 | AI8: =SQRT(POWER((H8+Q8+AE8),2)+POWER(P8,2))*POWER(6.3/Z8,2) -> 0.68036986 | AJ8: =37000/1.73/SQRT(POWER((G8+Q8+AE8),2)+P8*P8) -> 1179.7213 | AK8: =37000/2/SQRT(POWER((H8+Q8+AE8),2)+P8*P8) -> 880.99141 | AL8: =AK8/1.2 -> 734.15951 | AM8: =AK8/1.5 -> 587.3276 | AN8: =6300/(1.73*AH8) -> 6199.7365 | AO8: =SUM(6300/(2*AI8)) -> 4629.8347
A9: 1 | B9: КНС-5В | C9: К-47 | D9: 4.6 | E9: Н | F9: Ватинская | G9: 4.13 | H9: 6.96 | J9: 8.2 | P9: =0.314*I9+0.249*J9+0.195*M9+0.159*N9+0.06*O9 -> 2.0418 | Q9: =0.4*SUM(I9:O9) -> 3.28 | R9: =SQRT(POWER(P9,2)+POWER(Q9+G9,2)) -> 7.6861595 | S9: =SQRT(POWER(P9,2)+POWER(Q9+H9,2)) -> 10.441578 | T9: =37000/1.73/SQRT(POWER((G9+Q9),2)+P9*P9) -> 2782.5708 | U9: =37000/2/SQRT(P9*P9+POWER((H9+Q9),2)) -> 1771.7629 | V9: 1 | W9: ТМН 6300/35 | X9: 6.3 | Y9: 11 | Z9: 35 | AA9: 6.3 | AB9: 7.94 | AC9: 103,9/577,3 | AD9: 5 | AE9: =AB9/100*Z9*Z9/X9 -> 15.438889 | AF9: =SQRT(POWER(P9,2)+POWER(Q9+AE9+G9,2)) -> 22.939936 | AG9: =SQRT(POWER(P9,2)+POWER(Q9+AE9+H9,2)) -> 25.759936 | AH9: =SQRT(POWER((AE9+Q9+G9),2)+POWER(P9,2))*POWER(6.3/Z9,2) -> 0.74325393 | AI9: =SQRT(POWER((H9+Q9+AE9),2)+POWER(P9,2))*POWER(6.3/Z9,2) -> 0.83462191 | AJ9: =37000/1.73/SQRT(POWER((G9+Q9+AE9),2)+P9*P9) -> 932.3166 | AK9: =37000/2/SQRT(POWER((H9+Q9+AE9),2)+P9*P9) -> 718.1695 | AL9: =AK9/1.2 -> 598.47458 | AM9: =AK9/1.5 -> 478.77966 | AN9: =6300/(1.73*AH9) -> 4899.5617 | AO9: =SUM(6300/(2*AI9)) -> 3774.164
A10: 1 | D10: 4.6 | E10: Н | F10: Ватинская | G10: 4.13 | H10: 6.96 | J10: 8.2 | P10: =0.314*I10+0.249*J10+0.195*M10+0.159*N10+0.06*O10 -> 2.0418 | Q10: =0.4*SUM(I10:O10) -> 3.28 | R10: =SQRT(POWER(P10,2)+POWER(Q10+G10,2)) -> 7.6861595 | S10: =SQRT(POWER(P10,2)+POWER(Q10+H10,2)) -> 10.441578 | T10: =37000/1.73/SQRT(POWER((G10+Q10),2)+P10*P10) -> 2782.5708 | U10: =37000/2/SQRT(P10*P10+POWER((H10+Q10),2)) -> 1771.7629 | V10: 2 | W10: ТМН 6300/35 | X10: 6.3 | Y10: 11 | Z10: 35 | AA10: 6.3 | AB10: 7.96 | AC10: 103,9/577,3 | AD10: 5 | AE10: =AB10/100*Z10*Z10/X10 -> 15.477778 | AF10: =SQRT(POWER(P10,2)+POWER(Q10+AE10+G10,2)) -> 22.978671 | AG10: =SQRT(POWER(P10,2)+POWER(Q10+AE10+H10,2)) -> 25.798702 | AH10: =SQRT(POWER((AE10+Q10+G10),2)+POWER(P10,2))*POWER(6.3/Z10,2) -> 0.74450894 | AI10: =SQRT(POWER((H10+Q10+AE10),2)+POWER(P10,2))*POWER(6.3/Z10,2) -> 0.83587795 | AJ10: =37000/1.73/SQRT(POWER((G10+Q10+AE10),2)+P10*P10) -> 930.74501 | AK10: =37000/2/SQRT(POWER((H10+Q10+AE10),2)+P10*P10) -> 717.09033 | AL10: =AK10/1.2 -> 597.57528 | AM10: =AK10/1.5 -> 478.06022 | AN10: =6300/(1.73*AH10) -> 4891.3026 | AO10: =SUM(6300/(2*AI10)) -> 3768.4927
A11: 1 | B11: КНС-8В | C11: К-47 | D11: 5.6 | E11: Н | F11: Кирьяновская | G11: 2.55 | H11: 5.42 | J11: 4 | P11: =0.314*I11+0.249*J11+0.195*M11+0.159*N11+0.06*O11 -> 0.996 | Q11: =0.4*SUM(I11:O11) -> 1.6 | R11: =SQRT(POWER(P11,2)+POWER(Q11+G11,2)) -> 4.2678468 | S11: =SQRT(POWER(P11,2)+POWER(Q11+H11,2)) -> 7.0903044 | T11: =37000/1.73/SQRT(POWER((G11+Q11),2)+P11*P11) -> 5011.2585 | U11: =37000/2/SQRT(P11*P11+POWER((H11+Q11),2)) -> 2609.1969 | V11: 1 | W11: ТМН 6300/35 | X11: 6.3 | Y11: 11 | Z11: 35 | AA11: 6.3 | AB11: 7.41 | AC11: 104/577 | AD11: 12 | AE11: =AB11/100*Z11*Z11/X11 -> 14.408333 | AF11: =SQRT(POWER(P11,2)+POWER(Q11+AE11+G11,2)) -> 18.585041 | AG11: =SQRT(POWER(P11,2)+POWER(Q11+AE11+H11,2)) -> 21.451468 | AH11: =SQRT(POWER((AE11+Q11+G11),2)+POWER(P11,2))*POWER(6.3/Z11,2) -> 0.60215533 | AI11: =SQRT(POWER((H11+Q11+AE11),2)+POWER(P11,2))*POWER(6.3/Z11,2) -> 0.69502757 | AJ11: =37000/1.73/SQRT(POWER((G11+Q11+AE11),2)+P11*P11) -> 1150.7794 | AK11: =37000/2/SQRT(POWER((H11+Q11+AE11),2)+P11*P11) -> 862.41183 | AL11: =AK11/1.2 -> 718.67653 | AM11: =AK11/1.5 -> 574.94122 | AN11: =6300/(1.73*AH11) -> 6047.6397 | AO11: =SUM(6300/(2*AI11)) -> 4532.1943
A12: 1 | D12: 5.6 | E12: Н | F12: Кирьяновская | G12: 2.55 | H12: 5.42 | J12: 4 | P12: =0.314*I12+0.249*J12+0.195*M12+0.159*N12+0.06*O12 -> 0.996 | Q12: =0.4*SUM(I12:O12) -> 1.6 | R12: =SQRT(POWER(P12,2)+POWER(Q12+G12,2)) -> 4.2678468 | S12: =SQRT(POWER(P12,2)+POWER(Q12+H12,2)) -> 7.0903044 | T12: =37000/1.73/SQRT(POWER((G12+Q12),2)+P12*P12) -> 5011.2585 | U12: =37000/2/SQRT(P12*P12+POWER((H12+Q12),2)) -> 2609.1969 | V12: 2 | W12: ТМН 6300/35 | X12: 6.3 | Y12: 11 | Z12: 35 | AA12: 6.3 | AB12: 7.43 | AC12: 104/577 | AD12: 12 | AE12: =AB12/100*Z12*Z12/X12 -> 14.447222 | AF12: =SQRT(POWER(P12,2)+POWER(Q12+AE12+G12,2)) -> 18.623874 | AG12: =SQRT(POWER(P12,2)+POWER(Q12+AE12+H12,2)) -> 21.490315 | AH12: =SQRT(POWER((AE12+Q12+G12),2)+POWER(P12,2))*POWER(6.3/Z12,2) -> 0.60341352 | AI12: =SQRT(POWER((H12+Q12+AE12),2)+POWER(P12,2))*POWER(6.3/Z12,2) -> 0.69628621 | AJ12: =37000/1.73/SQRT(POWER((G12+Q12+AE12),2)+P12*P12) -> 1148.3799 | AK12: =37000/2/SQRT(POWER((H12+Q12+AE12),2)+P12*P12) -> 860.85289 | AL12: =AK12/1.2 -> 717.37741 | AM12: =AK12/1.5 -> 573.90193 | AN12: =6300/(1.73*AH12) -> 6035.0296 | AO12: =SUM(6300/(2*AI12)) -> 4524.0017
A13: 1 | B13: Куст-47 новая | C13: АльянсЭлектро | D13: 4.6 | E13: Н | F13: Ватинская | G13: 4.13 | H13: 6.96 | J13: 8.1 | P13: =0.314*I13+0.249*J13+0.195*M13+0.159*N13+0.06*O13 -> 2.0169 | Q13: =0.4*SUM(I13:O13) -> 3.24 | R13: =SQRT(POWER(P13,2)+POWER(Q13+G13,2)) -> 7.6409938 | S13: =SQRT(POWER(P13,2)+POWER(Q13+H13,2)) -> 10.397494 | T13: =37000/1.73/SQRT(POWER((G13+Q13),2)+P13*P13) -> 2799.0185 | U13: =37000/2/SQRT(P13*P13+POWER((H13+Q13),2)) -> 1779.2749 | V13: 1 | W13: 6300/35 | X13: 6.3 | Y13: 11 | Z13: 35 | AA13: 6.3 | AB13: 7.92 | AC13: 66/367 | AD13: 5 | AE13: =AB13/100*Z13*Z13/X13 -> 15.4 | AF13: =SQRT(POWER(P13,2)+POWER(Q13+AE13+G13,2)) -> 22.859151 | AG13: =SQRT(POWER(P13,2)+POWER(Q13+AE13+H13,2)) -> 25.679328 | AH13: =SQRT(POWER((AE13+Q13+G13),2)+POWER(P13,2))*POWER(6.3/Z13,2) -> 0.74063649 | AI13: =SQRT(POWER((H13+Q13+AE13),2)+POWER(P13,2))*POWER(6.3/Z13,2) -> 0.83201023 | AJ13: =37000/1.73/SQRT(POWER((G13+Q13+AE13),2)+P13*P13) -> 935.61144 | AK13: =37000/2/SQRT(POWER((H13+Q13+AE13),2)+P13*P13) -> 720.42384 | AL13: =AK13/1.2 -> 600.3532 | AM13: =AK13/1.5 -> 480.28256 | AN13: =6300/(1.73*AH13) -> 4916.8769 | AO13: =SUM(6300/(2*AI13)) -> 3786.0112
A14: 1 | D14: 4.6 | E14: Н | F14: Ватинская | G14: 4.13 | H14: 6.96 | J14: 8.1 | P14: =0.314*I14+0.249*J14+0.195*M14+0.159*N14+0.06*O14 -> 2.0169 | Q14: =0.4*SUM(I14:O14) -> 3.24 | R14: =SQRT(POWER(P14,2)+POWER(Q14+G14,2)) -> 7.6409938 | S14: =SQRT(POWER(P14,2)+POWER(Q14+H14,2)) -> 10.397494 | T14: =37000/1.73/SQRT(POWER((G14+Q14),2)+P14*P14) -> 2799.0185 | U14: =37000/2/SQRT(P14*P14+POWER((H14+Q14),2)) -> 1779.2749 | V14: 2 | W14: 6300/35 | X14: 6.3 | Y14: 11 | Z14: 35 | AA14: 6.3 | AB14: 8.1 | AC14: 66/367 | AD14: 5 | AE14: =AB14/100*Z14*Z14/X14 -> 15.75 | AF14: =SQRT(POWER(P14,2)+POWER(Q14+AE14+G14,2)) -> 23.207807 | AG14: =SQRT(POWER(P14,2)+POWER(Q14+AE14+H14,2)) -> 26.028261 | AH14: =SQRT(POWER((AE14+Q14+G14),2)+POWER(P14,2))*POWER(6.3/Z14,2) -> 0.75193293 | AI14: =SQRT(POWER((H14+Q14+AE14),2)+POWER(P14,2))*POWER(6.3/Z14,2) -> 0.84331567 | AJ14: =37000/1.73/SQRT(POWER((G14+Q14+AE14),2)+P14*P14) -> 921.55556 | AK14: =37000/2/SQRT(POWER((H14+Q14+AE14),2)+P14*P14) -> 710.76588 | AL14: =AK14/1.2 -> 592.3049 | AM14: =AK14/1.5 -> 473.84392 | AN14: =6300/(1.73*AH14) -> 4843.0097 | AO14: =SUM(6300/(2*AI14)) -> 3735.2561
A15: 1 | B15: Куст-53 | C15: К-59 | D15: 1.2 | E15: Н | F15: Мартыновская | G15: =121.5/1.73/14.327 -> 4.9020181 | H15: =121.5/(2*11.492) -> 5.2862861 | J15: 6.21 | P15: =0.314*I15+0.249*J15+0.195*M15+0.159*N15+0.06*O15 -> 1.54629 | Q15: =0.4*SUM(I15:O15) -> 2.484 | R15: =SQRT(POWER(P15,2)+POWER(Q15+G15,2)) -> 7.5461432 | S15: =SQRT(POWER(P15,2)+POWER(Q15+H15,2)) -> 7.9226485 | T15: =37000/1.73/SQRT(POWER((G15+Q15),2)+P15*P15) -> 2834.2006 | U15: =37000/2/SQRT(P15*P15+POWER((H15+Q15),2)) -> 2335.0777 | V15: 1 | W15: ТМН 6300/35 | X15: 6.3 | Y15: 11 | Z15: 35 | AA15: 6.3 | AB15: 8.01 | AC15: 103,9/577,3 | AE15: =AB15/100*Z15*Z15/X15 -> 15.575 | AF15: =SQRT(POWER(P15,2)+POWER(Q15+AE15+G15,2)) -> 23.013026 | AG15: =SQRT(POWER(P15,2)+POWER(Q15+AE15+H15,2)) -> 23.39644 | AH15: =SQRT(POWER((AE15+Q15+G15),2)+POWER(P15,2))*POWER(6.3/Z15,2) -> 0.74562204 | AI15: =SQRT(POWER((H15+Q15+AE15),2)+POWER(P15,2))*POWER(6.3/Z15,2) -> 0.75804465 | AJ15: =37000/1.73/SQRT(POWER((G15+Q15+AE15),2)+P15*P15) -> 929.35554 | AK15: =37000/2/SQRT(POWER((H15+Q15+AE15),2)+P15*P15) -> 790.71859 | AL15: =AK15/1.2 -> 658.93216 | AM15: =AK15/1.5 -> 527.14573 | AN15: =6300/(1.73*AH15) -> 4884.0006 | AO15: =SUM(6300/(2*AI15)) -> 4155.428
A16: 1 | D16: 1.2 | E16: Н | F16: Мартыновская | G16: =121.5/1.73/14.338 -> 4.8982573 | H16: =121.5/(2*11.613) -> 5.2312064 | J16: 6.21 | P16: =0.314*I16+0.249*J16+0.195*M16+0.159*N16+0.06*O16 -> 1.54629 | Q16: =0.4*SUM(I16:O16) -> 2.484 | R16: =SQRT(POWER(P16,2)+POWER(Q16+G16,2)) -> 7.5424622 | S16: =SQRT(POWER(P16,2)+POWER(Q16+H16,2)) -> 7.8686354 | T16: =37000/1.73/SQRT(POWER((G16+Q16),2)+P16*P16) -> 2835.5837 | U16: =37000/2/SQRT(P16*P16+POWER((H16+Q16),2)) -> 2351.1065 | V16: 2 | W16: ТМН 6300/35 | X16: 6.3 | Y16: 11 | Z16: 35 | AA16: 6.3 | AB16: 8.01 | AC16: 103,9/577,3 | AE16: =AB16/100*Z16*Z16/X16 -> 15.575 | AF16: =SQRT(POWER(P16,2)+POWER(Q16+AE16+G16,2)) -> 23.009274 | AG16: =SQRT(POWER(P16,2)+POWER(Q16+AE16+H16,2)) -> 23.341481 | AH16: =SQRT(POWER((AE16+Q16+G16),2)+POWER(P16,2))*POWER(6.3/Z16,2) -> 0.74550047 | AI16: =SQRT(POWER((H16+Q16+AE16),2)+POWER(P16,2))*POWER(6.3/Z16,2) -> 0.75626398 | AJ16: =37000/1.73/SQRT(POWER((G16+Q16+AE16),2)+P16*P16) -> 929.5071 | AK16: =37000/2/SQRT(POWER((H16+Q16+AE16),2)+P16*P16) -> 792.58039 | AL16: =AK16/1.2 -> 660.48366 | AM16: =AK16/1.5 -> 528.38693 | AN16: =6300/(1.73*AH16) -> 4884.7971 | AO16: =SUM(6300/(2*AI16)) -> 4165.2123
A17: 1 | B17: Куст-120 | C17: ST-7 | D17: 4.6 | E17: Н | F17: Ватинская | G17: 4.13 | H17: 6.96 | J17: 12.9 | P17: =0.314*I17+0.249*J17+0.195*M17+0.159*N17+0.06*O17 -> 3.2121 | Q17: =0.4*SUM(I17:O17) -> 5.16 | R17: =SQRT(POWER(P17,2)+POWER(Q17+G17,2)) -> 9.8296331 | S17: =SQRT(POWER(P17,2)+POWER(Q17+H17,2)) -> 12.53842 | T17: =37000/1.73/SQRT(POWER((G17+Q17),2)+P17*P17) -> 2175.7967 | U17: =37000/2/SQRT(P17*P17+POWER((H17+Q17),2)) -> 1475.465 | V17: 1 | W17: TONb 4000/35 | X17: 4 | Y17: 11 | Z17: 35 | AA17: 6.3 | AB17: 6.23 | AC17: 66/367 | AD17: 5 | AE17: =AB17/100*Z17*Z17/X17 -> 19.079375 | AF17: =SQRT(POWER(P17,2)+POWER(Q17+AE17+G17,2)) -> 28.55064 | AG17: =SQRT(POWER(P17,2)+POWER(Q17+AE17+H17,2)) -> 31.364288 | AH17: =SQRT(POWER((AE17+Q17+G17),2)+POWER(P17,2))*POWER(6.3/Z17,2) -> 0.92504072 | AI17: =SQRT(POWER((H17+Q17+AE17),2)+POWER(P17,2))*POWER(6.3/Z17,2) -> 1.0162029 | AJ17: =37000/1.73/SQRT(POWER((G17+Q17+AE17),2)+P17*P17) -> 749.09997 | AK17: =37000/2/SQRT(POWER((H17+Q17+AE17),2)+P17*P17) -> 589.84281 | AL17: =AK17/1.2 -> 491.53567 | AM17: =AK17/1.5 -> 393.22854 | AN17: =6300/(1.73*AH17) -> 3936.7115 | AO17: =SUM(6300/(2*AI17)) -> 3099.7745
A18: 1 | D18: 4.6 | E18: Н | F18: Ватинская | G18: 4.13 | H18: 6.96 | J18: 12.9 | P18: =0.314*I18+0.249*J18+0.195*M18+0.159*N18+0.06*O18 -> 3.2121 | Q18: =0.4*SUM(I18:O18) -> 5.16 | R18: =SQRT(POWER(P18,2)+POWER(Q18+G18,2)) -> 9.8296331 | S18: =SQRT(POWER(P18,2)+POWER(Q18+H18,2)) -> 12.53842 | T18: =37000/1.73/SQRT(POWER((G18+Q18),2)+P18*P18) -> 2175.7967 | U18: =37000/2/SQRT(P18*P18+POWER((H18+Q18),2)) -> 1475.465 | V18: 2 | W18: TONb 4000/35 | X18: 4 | Y18: 11 | Z18: 35 | AA18: 6.3 | AB18: 6.23 | AC18: 66/367 | AD18: 5 | AE18: =AB18/100*Z18*Z18/X18 -> 19.079375 | AF18: =SQRT(POWER(P18,2)+POWER(Q18+AE18+G18,2)) -> 28.55064 | AG18: =SQRT(POWER(P18,2)+POWER(Q18+AE18+H18,2)) -> 31.364288 | AH18: =SQRT(POWER((AE18+Q18+G18),2)+POWER(P18,2))*POWER(6.3/Z18,2) -> 0.92504072 | AI18: =SQRT(POWER((H18+Q18+AE18),2)+POWER(P18,2))*POWER(6.3/Z18,2) -> 1.0162029 | AJ18: =37000/1.73/SQRT(POWER((G18+Q18+AE18),2)+P18*P18) -> 749.09997 | AK18: =37000/2/SQRT(POWER((H18+Q18+AE18),2)+P18*P18) -> 589.84281 | AL18: =AK18/1.2 -> 491.53567 | AM18: =AK18/1.5 -> 393.22854 | AN18: =6300/(1.73*AH18) -> 3936.7115 | AO18: =SUM(6300/(2*AI18)) -> 3099.7745
A19: 1 | B19: Куст-211 | C19: ST-7 | D19: 4.6 | E19: Н | F19: Ватинская | G19: 4.13 | H19: 6.96 | J19: 20.4 | P19: =0.314*I19+0.249*J19+0.195*M19+0.159*N19+0.06*O19 -> 5.0796 | Q19: =0.4*SUM(I19:O19) -> 8.16 | R19: =SQRT(POWER(P19,2)+POWER(Q19+G19,2)) -> 13.298362 | S19: =SQRT(POWER(P19,2)+POWER(Q19+H19,2)) -> 15.950446 | T19: =37000/1.73/SQRT(POWER((G19+Q19),2)+P19*P19) -> 1608.2645 | U19: =37000/2/SQRT(P19*P19+POWER((H19+Q19),2)) -> 1159.8422 | V19: 1 | W19: ТМН 6300/35 | X19: 6.3 | Y19: 11 | Z19: 35 | AA19: 6.3 | AB19: 7.66 | AC19: 103,9/577,3 | AD19: 5 | AE19: =AB19/100*Z19*Z19/X19 -> 14.894444 | AF19: =SQRT(POWER(P19,2)+POWER(Q19+AE19+G19,2)) -> 27.654952 | AG19: =SQRT(POWER(P19,2)+POWER(Q19+AE19+H19,2)) -> 30.441242 | AH19: =SQRT(POWER((AE19+Q19+G19),2)+POWER(P19,2))*POWER(6.3/Z19,2) -> 0.89602044 | AI19: =SQRT(POWER((H19+Q19+AE19),2)+POWER(P19,2))*POWER(6.3/Z19,2) -> 0.98629624 | AJ19: =37000/1.73/SQRT(POWER((G19+Q19+AE19),2)+P19*P19) -> 773.3618 | AK19: =37000/2/SQRT(POWER((H19+Q19+AE19),2)+P19*P19) -> 607.72816 | AL19: =AK19/1.2 -> 506.44013 | AM19: =AK19/1.5 -> 405.15211 | AN19: =6300/(1.73*AH19) -> 4064.2137 | AO19: =SUM(6300/(2*AI19)) -> 3193.7666
A20: 1 | D20: 4.6 | E20: Н | F20: Ватинская | G20: 4.13 | H20: 6.96 | J20: 20.4 | P20: =0.314*I20+0.249*J20+0.195*M20+0.159*N20+0.06*O20 -> 5.0796 | Q20: =0.4*SUM(I20:O20) -> 8.16 | R20: =SQRT(POWER(P20,2)+POWER(Q20+G20,2)) -> 13.298362 | S20: =SQRT(POWER(P20,2)+POWER(Q20+H20,2)) -> 15.950446 | T20: =37000/1.73/SQRT(POWER((G20+Q20),2)+P20*P20) -> 1608.2645 | U20: =37000/2/SQRT(P20*P20+POWER((H20+Q20),2)) -> 1159.8422 | V20: 2 | W20: ТМН 6300/35 | X20: 6.3 | Y20: 11 | Z20: 35 | AA20: 6.3 | AB20: 7.61 | AC20: 103,9/577,3 | AD20: 5 | AE20: =AB20/100*Z20*Z20/X20 -> 14.797222 | AF20: =SQRT(POWER(P20,2)+POWER(Q20+AE20+G20,2)) -> 27.559389 | AG20: =SQRT(POWER(P20,2)+POWER(Q20+AE20+H20,2)) -> 30.345387 | AH20: =SQRT(POWER((AE20+Q20+G20),2)+POWER(P20,2))*POWER(6.3/Z20,2) -> 0.89292422 | AI20: =SQRT(POWER((H20+Q20+AE20),2)+POWER(P20,2))*POWER(6.3/Z20,2) -> 0.98319054 | AJ20: =37000/1.73/SQRT(POWER((G20+Q20+AE20),2)+P20*P20) -> 776.04344 | AK20: =37000/2/SQRT(POWER((H20+Q20+AE20),2)+P20*P20) -> 609.64785 | AL20: =AK20/1.2 -> 508.03987 | AM20: =AK20/1.5 -> 406.4319 | AN20: =6300/(1.73*AH20) -> 4078.3063 | AO20: =SUM(6300/(2*AI20)) -> 3203.8551
A21: 1 | B21: КРС | C21: ST-7 | D21: 3.4 | E21: Н | F21: Кирьяновская | G21: 2.55 | H21: 5.42 | I21: 5.3 | P21: =0.314*I21+0.249*J21+0.195*M21+0.159*N21+0.06*O21 -> 1.6642 | Q21: =0.4*SUM(I21:O21) -> 2.12 | R21: =SQRT(POWER(P21,2)+POWER(Q21+G21,2)) -> 4.957667 | S21: =SQRT(POWER(P21,2)+POWER(Q21+H21,2)) -> 7.7214741 | T21: =37000/1.73/SQRT(POWER((G21+Q21),2)+P21*P21) -> 4313.9814 | U21: =37000/2/SQRT(P21*P21+POWER((H21+Q21),2)) -> 2395.9156 | V21: 1 | W21: ТМН 4000/35 | X21: 4 | Y21: 11 | Z21: 35 | AA21: 6.3 | AB21: 7.2 | AC21: 66/367 | AE21: =AB21/100*Z21*Z21/X21 -> 22.05 | AF21: =SQRT(POWER(P21,2)+POWER(Q21+AE21+G21,2)) -> 26.771775 | AG21: =SQRT(POWER(P21,2)+POWER(Q21+AE21+H21,2)) -> 29.636762 | AH21: =SQRT(POWER((AE21+Q21+G21),2)+POWER(P21,2))*POWER(6.3/Z21,2) -> 0.86740553 | AI21: =SQRT(POWER((H21+Q21+AE21),2)+POWER(P21,2))*POWER(6.3/Z21,2) -> 0.96023109 | AJ21: =37000/1.73/SQRT(POWER((G21+Q21+AE21),2)+P21*P21) -> 798.87429 | AK21: =37000/2/SQRT(POWER((H21+Q21+AE21),2)+P21*P21) -> 624.22474 | AL21: =AK21/1.2 -> 520.18728 | AM21: =AK21/1.5 -> 416.14983 | AN21: =6300/(1.73*AH21) -> 4198.2883 | AO21: =SUM(6300/(2*AI21)) -> 3280.4603
A22: 1 | D22: 3.4 | E22: Н | F22: Кирьяновская | G22: 2.55 | H22: 5.42 | I22: 5.3 | P22: =0.314*I22+0.249*J22+0.195*M22+0.159*N22+0.06*O22 -> 1.6642 | Q22: =0.4*SUM(I22:O22) -> 2.12 | R22: =SQRT(POWER(P22,2)+POWER(Q22+G22,2)) -> 4.957667 | S22: =SQRT(POWER(P22,2)+POWER(Q22+H22,2)) -> 7.7214741 | T22: =37000/1.73/SQRT(POWER((G22+Q22),2)+P22*P22) -> 4313.9814 | U22: =37000/2/SQRT(P22*P22+POWER((H22+Q22),2)) -> 2395.9156 | V22: 2 | W22: ТМН 4000/35 | X22: 4 | Y22: 11 | Z22: 35 | AA22: 6.3 | AB22: 7.2 | AC22: 66/367 | AE22: =AB22/100*Z22*Z22/X22 -> 22.05 | AF22: =SQRT(POWER(P22,2)+POWER(Q22+AE22+G22,2)) -> 26.771775 | AG22: =SQRT(POWER(P22,2)+POWER(Q22+AE22+H22,2)) -> 29.636762 | AH22: =SQRT(POWER((AE22+Q22+G22),2)+POWER(P22,2))*POWER(6.3/Z22,2) -> 0.86740553 | AI22: =SQRT(POWER((H22+Q22+AE22),2)+POWER(P22,2))*POWER(6.3/Z22,2) -> 0.96023109 | AJ22: =37000/1.73/SQRT(POWER((G22+Q22+AE22),2)+P22*P22) -> 798.87429 | AK22: =37000/2/SQRT(POWER((H22+Q22+AE22),2)+P22*P22) -> 624.22474 | AL22: =AK22/1.2 -> 520.18728 | AM22: =AK22/1.5 -> 416.14983 | AN22: =6300/(1.73*AH22) -> 4198.2883 | AO22: =SUM(6300/(2*AI22)) -> 3280.4603
A23: 1 | B23: Куст-220 | C23: К-63 | D23: 5.6 | E23: Н | F23: Кирьяновская | G23: 2.55 | H23: 5.42 | J23: 10.92 | K23: 0.08 | P23: =0.314*I23+0.249*J23+0.37*K23+0.195*M23+0.159*N23+0.06*O23 -> 2.74868 | Q23: =0.4*I23+0.4*J23+0.083*K23+0.4*M23+0.4*N23+0.4*O23 -> 4.37464 | R23: =SQRT(POWER(P23,2)+POWER(Q23+G23,2)) -> 7.4502269 | S23: =SQRT(POWER(P23,2)+POWER(Q23+H23,2)) -> 10.173014 | T23: =37000/1.73/SQRT(POWER((G23+Q23),2)+P23*P23) -> 2870.6888 | U23: =37000/2/SQRT(P23*P23+POWER((H23+Q23),2)) -> 1818.5368 | V23: 1 | W23: TМН-4000/35-73 | X23: 4 | Y23: 11 | Z23: 35 | AA23: 6.3 | AB23: 7.6 | AC23: 66/367 | AD23: 10 | AE23: =AB23/100*Z23*Z23/X23 -> 23.275 | AF23: =SQRT(POWER(P23,2)+POWER(Q23+AE23+G23,2)) -> 30.32447 | AG23: =SQRT(POWER(P23,2)+POWER(Q23+AE23+H23,2)) -> 33.183676 | AH23: =SQRT(POWER((AE23+Q23+G23),2)+POWER(P23,2))*POWER(6.3/Z23,2) -> 0.98251284 | AI23: =SQRT(POWER((H23+Q23+AE23),2)+POWER(P23,2))*POWER(6.3/Z23,2) -> 1.0751511 | AJ23: =37000/1.73/SQRT(POWER((G23+Q23+AE23),2)+P23*P23) -> 705.28135 | AK23: =37000/2/SQRT(POWER((H23+Q23+AE23),2)+P23*P23) -> 557.50304 | AL23: =AK23/1.2 -> 464.58586 | AM23: =AK23/1.5 -> 371.66869 | AN23: =6300/(1.73*AH23) -> 3706.4335 | AO23: =SUM(6300/(2*AI23)) -> 2929.8208
A24: 1 | D24: 5.6 | E24: Н | F24: Кирьяновская | G24: 2.55 | H24: 5.42 | J24: 10.92 | K24: 0.08 | P24: =0.314*I24+0.249*J24+0.37*K24+0.195*M24+0.159*N24+0.06*O24 -> 2.74868 | Q24: =0.4*I24+0.4*J24+0.083*K24+0.4*M24+0.4*N24+0.4*O24 -> 4.37464 | R24: =SQRT(POWER(P24,2)+POWER(Q24+G24,2)) -> 7.4502269 | S24: =SQRT(POWER(P24,2)+POWER(Q24+H24,2)) -> 10.173014 | T24: =37000/1.73/SQRT(POWER((G24+Q24),2)+P24*P24) -> 2870.6888 | U24: =37000/2/SQRT(P24*P24+POWER((H24+Q24),2)) -> 1818.5368 | V24: 2 | W24: TМН-4000/35-73 | X24: 4 | Y24: 11 | Z24: 35 | AA24: 6.3 | AB24: 7.69 | AC24: 66/367 | AD24: 10 | AE24: =AB24/100*Z24*Z24/X24 -> 23.550625 | AF24: =SQRT(POWER(P24,2)+POWER(Q24+AE24+G24,2)) -> 30.598971 | AG24: =SQRT(POWER(P24,2)+POWER(Q24+AE24+H24,2)) -> 33.458361 | AH24: =SQRT(POWER((AE24+Q24+G24),2)+POWER(P24,2))*POWER(6.3/Z24,2) -> 0.99140666 | AI24: =SQRT(POWER((H24+Q24+AE24),2)+POWER(P24,2))*POWER(6.3/Z24,2) -> 1.0840509 | AJ24: =37000/1.73/SQRT(POWER((G24+Q24+AE24),2)+P24*P24) -> 698.95433 | AK24: =37000/2/SQRT(POWER((H24+Q24+AE24),2)+P24*P24) -> 552.92606 | AL24: =AK24/1.2 -> 460.77172 | AM24: =AK24/1.5 -> 368.61738 | AN24: =6300/(1.73*AH24) -> 3673.1834 | AO24: =SUM(6300/(2*AI24)) -> 2905.7676
A25: 1 | B25: ДНС-2В | C25: К-47 | D25: 4.6 | E25: А | F25: Ватинская | G25: 4.13 | H25: 6.96 | J25: 6.1 | P25: =0.314*I25+0.249*J25+0.195*M25+0.159*N25+0.06*O25 -> 1.5189 | Q25: =0.4*SUM(I25:O25) -> 2.44 | R25: =SQRT(POWER(P25,2)+POWER(Q25+G25,2)) -> 6.7432898 | S25: =SQRT(POWER(P25,2)+POWER(Q25+H25,2)) -> 9.5219251 | T25: =37000/1.73/SQRT(POWER((G25+Q25),2)+P25*P25) -> 3171.6393 | U25: =37000/2/SQRT(P25*P25+POWER((H25+Q25),2)) -> 1942.8844 | V25: 1 | W25: TМН-4000/35 | X25: 4 | Y25: 11 | Z25: 35 | AA25: 6.3 | AB25: 7.67 | AC25: 66/367 | AD25: 9 | AE25: =AB25/100*Z25*Z25/X25 -> 23.489375 | AF25: =SQRT(POWER(P25,2)+POWER(Q25+AE25+G25,2)) -> 30.097726 | AG25: =SQRT(POWER(P25,2)+POWER(Q25+AE25+H25,2)) -> 32.924429 | AH25: =SQRT(POWER((AE25+Q25+G25),2)+POWER(P25,2))*POWER(6.3/Z25,2) -> 0.97516631 | AI25: =SQRT(POWER((H25+Q25+AE25),2)+POWER(P25,2))*POWER(6.3/Z25,2) -> 1.0667515 | AJ25: =37000/1.73/SQRT(POWER((G25+Q25+AE25),2)+P25*P25) -> 710.59467 | AK25: =37000/2/SQRT(POWER((H25+Q25+AE25),2)+P25*P25) -> 561.89281 | AL25: =AK25/1.2 -> 468.24401 | AM25: =AK25/1.5 -> 374.5952 | AN25: =6300/(1.73*AH25) -> 3734.3564 | AO25: =SUM(6300/(2*AI25)) -> 2952.8901
A26: 1 | D26: 4.6 | E26: А | F26: Ватинская | G26: 4.13 | H26: 6.96 | J26: 6.1 | P26: =0.314*I26+0.249*J26+0.195*M26+0.159*N26+0.06*O26 -> 1.5189 | Q26: =0.4*SUM(I26:O26) -> 2.44 | R26: =SQRT(POWER(P26,2)+POWER(Q26+G26,2)) -> 6.7432898 | S26: =SQRT(POWER(P26,2)+POWER(Q26+H26,2)) -> 9.5219251 | T26: =37000/1.73/SQRT(POWER((G26+Q26),2)+P26*P26) -> 3171.6393 | U26: =37000/2/SQRT(P26*P26+POWER((H26+Q26),2)) -> 1942.8844 | V26: 2 | W26: TМН-4000/35 | X26: 4 | Y26: 11 | Z26: 35 | AA26: 6.3 | AB26: 7.6 | AC26: 66/367 | AD26: 12 | AE26: =AB26/100*Z26*Z26/X26 -> 23.275 | AF26: =SQRT(POWER(P26,2)+POWER(Q26+AE26+G26,2)) -> 29.883626 | AG26: =SQRT(POWER(P26,2)+POWER(Q26+AE26+H26,2)) -> 32.710284 | AH26: =SQRT(POWER((AE26+Q26+G26),2)+POWER(P26,2))*POWER(6.3/Z26,2) -> 0.96822947 | AI26: =SQRT(POWER((H26+Q26+AE26),2)+POWER(P26,2))*POWER(6.3/Z26,2) -> 1.0598132 | AJ26: =37000/1.73/SQRT(POWER((G26+Q26+AE26),2)+P26*P26) -> 715.68569 | AK26: =37000/2/SQRT(POWER((H26+Q26+AE26),2)+P26*P26) -> 565.57137 | AL26: =AK26/1.2 -> 471.30947 | AM26: =AK26/1.5 -> 377.04758 | AN26: =6300/(1.73*AH26) -> 3761.111 | AO26: =SUM(6300/(2*AI26)) -> 2972.2219
A27: 1 | B27: КНС-4В | C27: К-47 | D27: 4.6 | E27: А | F27: Ватинская | G27: 4.13 | H27: 6.96 | J27: 10.58 | P27: =0.314*I27+0.249*J27+0.195*M27+0.159*N27+0.06*O27 -> 2.63442 | Q27: =0.4*SUM(I27:O27) -> 4.232 | R27: =SQRT(POWER(P27,2)+POWER(Q27+G27,2)) -> 8.7671667 | S27: =SQRT(POWER(P27,2)+POWER(Q27+H27,2)) -> 11.497871 | T27: =37000/1.73/SQRT(POWER((G27+Q27),2)+P27*P27) -> 2439.4749 | U27: =37000/2/SQRT(P27*P27+POWER((H27+Q27),2)) -> 1608.9936 | V27: 1 | W27: ТМН 6300/35 | X27: 6.3 | Y27: 11 | Z27: 35 | AA27: 6.3 | AB27: 7.82 | AC27: 103,9/577,3 | AE27: =AB27/100*Z27*Z27/X27 -> 15.205556 | AF27: =SQRT(POWER(P27,2)+POWER(Q27+AE27+G27,2)) -> 23.714338 | AG27: =SQRT(POWER(P27,2)+POWER(Q27+AE27+H27,2)) -> 26.528685 | AH27: =SQRT(POWER((AE27+Q27+G27),2)+POWER(P27,2))*POWER(6.3/Z27,2) -> 0.76834456 | AI27: =SQRT(POWER((H27+Q27+AE27),2)+POWER(P27,2))*POWER(6.3/Z27,2) -> 0.85952938 | AJ27: =37000/1.73/SQRT(POWER((G27+Q27+AE27),2)+P27*P27) -> 901.87139 | AK27: =37000/2/SQRT(POWER((H27+Q27+AE27),2)+P27*P27) -> 697.35836 | AL27: =AK27/1.2 -> 581.13197 | AM27: =AK27/1.5 -> 464.90557 | AN27: =6300/(1.73*AH27) -> 4739.5643 | AO27: =SUM(6300/(2*AI27)) -> 3664.7962
A28: 1 | D28: 4.6 | E28: А | F28: Ватинская | G28: 4.13 | H28: 6.96 | J28: 10.58 | P28: =0.314*I28+0.249*J28+0.195*M28+0.159*N28+0.06*O28 -> 2.63442 | Q28: =0.4*SUM(I28:O28) -> 4.232 | R28: =SQRT(POWER(P28,2)+POWER(Q28+G28,2)) -> 8.7671667 | S28: =SQRT(POWER(P28,2)+POWER(Q28+H28,2)) -> 11.497871 | T28: =37000/1.73/SQRT(POWER((G28+Q28),2)+P28*P28) -> 2439.4749 | U28: =37000/2/SQRT(P28*P28+POWER((H28+Q28),2)) -> 1608.9936 | V28: 2 | W28: ТМН 6300/35 | X28: 6.3 | Y28: 11 | Z28: 35 | AA28: 6.3 | AB28: 7.94 | AC28: 103,9/577,3 | AE28: =AB28/100*Z28*Z28/X28 -> 15.438889 | AF28: =SQRT(POWER(P28,2)+POWER(Q28+AE28+G28,2)) -> 23.946241 | AG28: =SQRT(POWER(P28,2)+POWER(Q28+AE28+H28,2)) -> 26.760875 | AH28: =SQRT(POWER((AE28+Q28+G28),2)+POWER(P28,2))*POWER(6.3/Z28,2) -> 0.77585822 | AI28: =SQRT(POWER((H28+Q28+AE28),2)+POWER(P28,2))*POWER(6.3/Z28,2) -> 0.86705234 | AJ28: =37000/1.73/SQRT(POWER((G28+Q28+AE28),2)+P28*P28) -> 893.13737 | AK28: =37000/2/SQRT(POWER((H28+Q28+AE28),2)+P28*P28) -> 691.30775 | AL28: =AK28/1.2 -> 576.08979 | AM28: =AK28/1.5 -> 460.87183 | AN28: =6300/(1.73*AH28) -> 4693.6649 | AO28: =SUM(6300/(2*AI28)) -> 3632.9987
A29: 1 | B29: КНС-5В | C29: К-47 | D29: 5.6 | E29: А | F29: Кирьяновская | G29: 2.55 | H29: 5.42 | J29: 10.63 | P29: =0.314*I29+0.249*J29+0.195*M29+0.159*N29+0.06*O29 -> 2.64687 | Q29: =0.4*SUM(I29:O29) -> 4.252 | R29: =SQRT(POWER(P29,2)+POWER(Q29+G29,2)) -> 7.2988441 | S29: =SQRT(POWER(P29,2)+POWER(Q29+H29,2)) -> 10.027637 | T29: =37000/1.73/SQRT(POWER((G29+Q29),2)+P29*P29) -> 2930.2288 | U29: =37000/2/SQRT(P29*P29+POWER((H29+Q29),2)) -> 1844.9012 | V29: 1 | W29: ТМН 6300/35 | X29: 6.3 | Y29: 11 | Z29: 35 | AA29: 6.3 | AB29: 7.94 | AC29: 103,9/577,3 | AD29: 5 | AE29: =AB29/100*Z29*Z29/X29 -> 15.438889 | AF29: =SQRT(POWER(P29,2)+POWER(Q29+AE29+G29,2)) -> 22.397836 | AG29: =SQRT(POWER(P29,2)+POWER(Q29+AE29+H29,2)) -> 25.250003 | AH29: =SQRT(POWER((AE29+Q29+G29),2)+POWER(P29,2))*POWER(6.3/Z29,2) -> 0.72568989 | AI29: =SQRT(POWER((H29+Q29+AE29),2)+POWER(P29,2))*POWER(6.3/Z29,2) -> 0.8181001 | AJ29: =37000/1.73/SQRT(POWER((G29+Q29+AE29),2)+P29*P29) -> 954.88168 | AK29: =37000/2/SQRT(POWER((H29+Q29+AE29),2)+P29*P29) -> 732.67317 | AL29: =AK29/1.2 -> 610.56098 | AM29: =AK29/1.5 -> 488.44878 | AN29: =6300/(1.73*AH29) -> 5018.147 | AO29: =SUM(6300/(2*AI29)) -> 3850.3846
A30: 1 | D30: 5.6 | E30: А | F30: Кирьяновская | G30: 2.55 | H30: 5.42 | J30: 10.63 | P30: =0.314*I30+0.249*J30+0.195*M30+0.159*N30+0.06*O30 -> 2.64687 | Q30: =0.4*SUM(I30:O30) -> 4.252 | R30: =SQRT(POWER(P30,2)+POWER(Q30+G30,2)) -> 7.2988441 | S30: =SQRT(POWER(P30,2)+POWER(Q30+H30,2)) -> 10.027637 | T30: =37000/1.73/SQRT(POWER((G30+Q30),2)+P30*P30) -> 2930.2288 | U30: =37000/2/SQRT(P30*P30+POWER((H30+Q30),2)) -> 1844.9012 | V30: 2 | W30: ТМН 6300/35 | X30: 6.3 | Y30: 11 | Z30: 35 | AA30: 6.3 | AB30: 7.96 | AC30: 103,9/577,3 | AD30: 5 | AE30: =AB30/100*Z30*Z30/X30 -> 15.477778 | AF30: =SQRT(POWER(P30,2)+POWER(Q30+AE30+G30,2)) -> 22.436453 | AG30: =SQRT(POWER(P30,2)+POWER(Q30+AE30+H30,2)) -> 25.288678 | AH30: =SQRT(POWER((AE30+Q30+G30),2)+POWER(P30,2))*POWER(6.3/Z30,2) -> 0.72694107 | AI30: =SQRT(POWER((H30+Q30+AE30),2)+POWER(P30,2))*POWER(6.3/Z30,2) -> 0.81935317 | AJ30: =37000/1.73/SQRT(POWER((G30+Q30+AE30),2)+P30*P30) -> 953.23817 | AK30: =37000/2/SQRT(POWER((H30+Q30+AE30),2)+P30*P30) -> 731.55267 | AL30: =AK30/1.2 -> 609.62722 | AM30: =AK30/1.5 -> 487.70178 | AN30: =6300/(1.73*AH30) -> 5009.5099 | AO30: =SUM(6300/(2*AI30)) -> 3844.496
A31: 1 | B31: КНС-8В | C31: К-47 | D31: 4.6 | E31: А | F31: Ватинская | G31: 4.13 | H31: 6.96 | J31: 6.83 | P31: =0.314*I31+0.249*J31+0.195*M31+0.159*N31+0.06*O31 -> 1.70067 | Q31: =0.4*SUM(I31:O31) -> 2.732 | R31: =SQRT(POWER(P31,2)+POWER(Q31+G31,2)) -> 7.0696055 | S31: =SQRT(POWER(P31,2)+POWER(Q31+H31,2)) -> 9.8400784 | T31: =37000/1.73/SQRT(POWER((G31+Q31),2)+P31*P31) -> 3025.2442 | U31: =37000/2/SQRT(P31*P31+POWER((H31+Q31),2)) -> 1880.0663 | V31: 1 | W31: ТМН 6300/35 | X31: 6.3 | Y31: 11 | Z31: 35 | AA31: 6.3 | AB31: 7.41 | AC31: 103,9/577,3 | AD31: 12 | AE31: =AB31/100*Z31*Z31/X31 -> 14.408333 | AF31: =SQRT(POWER(P31,2)+POWER(Q31+AE31+G31,2)) -> 21.338214 | AG31: =SQRT(POWER(P31,2)+POWER(Q31+AE31+H31,2)) -> 24.160264 | AH31: =SQRT(POWER((AE31+Q31+G31),2)+POWER(P31,2))*POWER(6.3/Z31,2) -> 0.69135812 | AI31: =SQRT(POWER((H31+Q31+AE31),2)+POWER(P31,2))*POWER(6.3/Z31,2) -> 0.78279255 | AJ31: =37000/1.73/SQRT(POWER((G31+Q31+AE31),2)+P31*P31) -> 1002.2996 | AK31: =37000/2/SQRT(POWER((H31+Q31+AE31),2)+P31*P31) -> 765.72012 | AL31: =AK31/1.2 -> 638.1001 | AM31: =AK31/1.5 -> 510.48008 | AN31: =6300/(1.73*AH31) -> 5267.3403 | AO31: =SUM(6300/(2*AI31)) -> 4024.0547
A32: 1 | D32: 4.6 | E32: А | F32: Ватинская | G32: 4.13 | H32: 6.96 | J32: 6.83 | P32: =0.314*I32+0.249*J32+0.195*M32+0.159*N32+0.06*O32 -> 1.70067 | Q32: =0.4*SUM(I32:O32) -> 2.732 | R32: =SQRT(POWER(P32,2)+POWER(Q32+G32,2)) -> 7.0696055 | S32: =SQRT(POWER(P32,2)+POWER(Q32+H32,2)) -> 9.8400784 | T32: =37000/1.73/SQRT(POWER((G32+Q32),2)+P32*P32) -> 3025.2442 | U32: =37000/2/SQRT(P32*P32+POWER((H32+Q32),2)) -> 1880.0663 | V32: 2 | W32: ТМН 6300/35 | X32: 6.3 | Y32: 11 | Z32: 35 | AA32: 6.3 | AB32: 7.43 | AC32: 103,9/577,3 | AD32: 12 | AE32: =AB32/100*Z32*Z32/X32 -> 14.447222 | AF32: =SQRT(POWER(P32,2)+POWER(Q32+AE32+G32,2)) -> 21.376979 | AG32: =SQRT(POWER(P32,2)+POWER(Q32+AE32+H32,2)) -> 24.199056 | AH32: =SQRT(POWER((AE32+Q32+G32),2)+POWER(P32,2))*POWER(6.3/Z32,2) -> 0.69261412 | AI32: =SQRT(POWER((H32+Q32+AE32),2)+POWER(P32,2))*POWER(6.3/Z32,2) -> 0.78404943 | AJ32: =37000/1.73/SQRT(POWER((G32+Q32+AE32),2)+P32*P32) -> 1000.482 | AK32: =37000/2/SQRT(POWER((H32+Q32+AE32),2)+P32*P32) -> 764.49262 | AL32: =AK32/1.2 -> 637.07718 | AM32: =AK32/1.5 -> 509.66175 | AN32: =6300/(1.73*AH32) -> 5257.7884 | AO32: =SUM(6300/(2*AI32)) -> 4017.6039
A33: 1 | B33: Куст-47 | C33: ST-7 | D33: 5.6 | E33: А | F33: Кирьяновская | G33: 2.55 | H33: 5.42 | J33: 10.53 | P33: =0.314*I33+0.249*J33+0.195*M33+0.159*N33+0.06*O33 -> 2.62197 | Q33: =0.4*SUM(I33:O33) -> 4.212 | R33: =SQRT(POWER(P33,2)+POWER(Q33+G33,2)) -> 7.2525424 | S33: =SQRT(POWER(P33,2)+POWER(Q33+H33,2)) -> 9.9824922 | T33: =37000/1.73/SQRT(POWER((G33+Q33),2)+P33*P33) -> 2948.936 | U33: =37000/2/SQRT(P33*P33+POWER((H33+Q33),2)) -> 1853.2446 | V33: 1 | W33: TONb 4000/35 | X33: 4 | Y33: 11 | Z33: 35 | AA33: 6.3 | AB33: 6.14 | AC33: 66/367 | AD33: 5 | AE33: =AB33/100*Z33*Z33/X33 -> 18.80375 | AF33: =SQRT(POWER(P33,2)+POWER(Q33+AE33+G33,2)) -> 25.69985 | AG33: =SQRT(POWER(P33,2)+POWER(Q33+AE33+H33,2)) -> 28.556376 | AH33: =SQRT(POWER((AE33+Q33+G33),2)+POWER(P33,2))*POWER(6.3/Z33,2) -> 0.83267515 | AI33: =SQRT(POWER((H33+Q33+AE33),2)+POWER(P33,2))*POWER(6.3/Z33,2) -> 0.92522658 | AJ33: =37000/1.73/SQRT(POWER((G33+Q33+AE33),2)+P33*P33) -> 832.19486 | AK33: =37000/2/SQRT(POWER((H33+Q33+AE33),2)+P33*P33) -> 647.84131 | AL33: =AK33/1.2 -> 539.86776 | AM33: =AK33/1.5 -> 431.89421 | AN33: =6300/(1.73*AH33) -> 4373.3964 | AO33: =SUM(6300/(2*AI33)) -> 3404.5715
A34: 1 | D34: 5.6 | E34: А | F34: Кирьяновская | G34: 2.55 | H34: 5.42 | J34: 10.53 | P34: =0.314*I34+0.249*J34+0.195*M34+0.159*N34+0.06*O34 -> 2.62197 | Q34: =0.4*SUM(I34:O34) -> 4.212 | R34: =SQRT(POWER(P34,2)+POWER(Q34+G34,2)) -> 7.2525424 | S34: =SQRT(POWER(P34,2)+POWER(Q34+H34,2)) -> 9.9824922 | T34: =37000/1.73/SQRT(POWER((G34+Q34),2)+P34*P34) -> 2948.936 | U34: =37000/2/SQRT(P34*P34+POWER((H34+Q34),2)) -> 1853.2446 | V34: 2 | W34: TONb 4000/35 | X34: 4 | Y34: 11 | Z34: 35 | AA34: 6.3 | AB34: 6.26 | AC34: 66/367 | AD34: 5 | AE34: =AB34/100*Z34*Z34/X34 -> 19.17125 | AF34: =SQRT(POWER(P34,2)+POWER(Q34+AE34+G34,2)) -> 26.06546 | AG34: =SQRT(POWER(P34,2)+POWER(Q34+AE34+H34,2)) -> 28.922343 | AH34: =SQRT(POWER((AE34+Q34+G34),2)+POWER(P34,2))*POWER(6.3/Z34,2) -> 0.84452089 | AI34: =SQRT(POWER((H34+Q34+AE34),2)+POWER(P34,2))*POWER(6.3/Z34,2) -> 0.93708392 | AJ34: =37000/1.73/SQRT(POWER((G34+Q34+AE34),2)+P34*P34) -> 820.52201 | AK34: =37000/2/SQRT(POWER((H34+Q34+AE34),2)+P34*P34) -> 639.64389 | AL34: =AK34/1.2 -> 533.03657 | AM34: =AK34/1.5 -> 426.42926 | AN34: =6300/(1.73*AH34) -> 4312.0526 | AO34: =SUM(6300/(2*AI34)) -> 3361.4919
A35: 1 | B35: Куст-47 новая | C35: АльянсЭлектро | D35: 5.6 | E35: А | F35: Кирьяновская | G35: 2.55 | H35: 5.42 | J35: 10.53 | P35: =0.314*I35+0.249*J35+0.195*M35+0.159*N35+0.06*O35 -> 2.62197 | Q35: =0.4*SUM(I35:O35) -> 4.212 | R35: =SQRT(POWER(P35,2)+POWER(Q35+G35,2)) -> 7.2525424 | S35: =SQRT(POWER(P35,2)+POWER(Q35+H35,2)) -> 9.9824922 | T35: =37000/1.73/SQRT(POWER((G35+Q35),2)+P35*P35) -> 2948.936 | U35: =37000/2/SQRT(P35*P35+POWER((H35+Q35),2)) -> 1853.2446 | V35: 1 | W35: 6300/35 | X35: 6.3 | Y35: 11 | Z35: 35 | AA35: 6.3 | AB35: 7.92 | AC35: 66/367 | AD35: 5 | AE35: =AB35/100*Z35*Z35/X35 -> 15.4 | AF35: =SQRT(POWER(P35,2)+POWER(Q35+AE35+G35,2)) -> 22.316563 | AG35: =SQRT(POWER(P35,2)+POWER(Q35+AE35+H35,2)) -> 25.168944 | AH35: =SQRT(POWER((AE35+Q35+G35),2)+POWER(P35,2))*POWER(6.3/Z35,2) -> 0.72305663 | AI35: =SQRT(POWER((H35+Q35+AE35),2)+POWER(P35,2))*POWER(6.3/Z35,2) -> 0.81547379 | AJ35: =37000/1.73/SQRT(POWER((G35+Q35+AE35),2)+P35*P35) -> 958.3592 | AK35: =37000/2/SQRT(POWER((H35+Q35+AE35),2)+P35*P35) -> 735.03282 | AL35: =AK35/1.2 -> 612.52735 | AM35: =AK35/1.5 -> 490.02188 | AN35: =6300/(1.73*AH35) -> 5036.4222 | AO35: =SUM(6300/(2*AI35)) -> 3862.7851
A36: 1 | D36: 5.6 | E36: А | F36: Кирьяновская | G36: 2.55 | H36: 5.42 | J36: 10.53 | P36: =0.314*I36+0.249*J36+0.195*M36+0.159*N36+0.06*O36 -> 2.62197 | Q36: =0.4*SUM(I36:O36) -> 4.212 | R36: =SQRT(POWER(P36,2)+POWER(Q36+G36,2)) -> 7.2525424 | S36: =SQRT(POWER(P36,2)+POWER(Q36+H36,2)) -> 9.9824922 | T36: =37000/1.73/SQRT(POWER((G36+Q36),2)+P36*P36) -> 2948.936 | U36: =37000/2/SQRT(P36*P36+POWER((H36+Q36),2)) -> 1853.2446 | V36: 2 | W36: 6300/35 | X36: 6.3 | Y36: 11 | Z36: 35 | AA36: 6.3 | AB36: 8.1 | AC36: 66/367 | AD36: 5 | AE36: =AB36/100*Z36*Z36/X36 -> 15.75 | AF36: =SQRT(POWER(P36,2)+POWER(Q36+AE36+G36,2)) -> 22.664176 | AG36: =SQRT(POWER(P36,2)+POWER(Q36+AE36+H36,2)) -> 25.517066 | AH36: =SQRT(POWER((AE36+Q36+G36),2)+POWER(P36,2))*POWER(6.3/Z36,2) -> 0.7343193 | AI36: =SQRT(POWER((H36+Q36+AE36),2)+POWER(P36,2))*POWER(6.3/Z36,2) -> 0.82675293 | AJ36: =37000/1.73/SQRT(POWER((G36+Q36+AE36),2)+P36*P36) -> 943.66031 | AK36: =37000/2/SQRT(POWER((H36+Q36+AE36),2)+P36*P36) -> 725.00499 | AL36: =AK36/1.2 -> 604.17082 | AM36: =AK36/1.5 -> 483.33666 | AN36: =6300/(1.73*AH36) -> 4959.1758 | AO36: =SUM(6300/(2*AI36)) -> 3810.0863
A37: 1 | B37: Куст-53 | C37: К-59 | D37: 3.4 | E37: А | F37: Мартыновская | G37: =G15 -> 4.9020181 | H37: =H15 -> 5.2862861 | J37: 8.99 | P37: =0.314*I37+0.249*J37+0.195*M37+0.159*N37+0.06*O37 -> 2.23851 | Q37: =0.4*SUM(I37:O37) -> 3.596 | R37: =SQRT(POWER(P37,2)+POWER(Q37+G37,2)) -> 8.787903 | S37: =SQRT(POWER(P37,2)+POWER(Q37+H37,2)) -> 9.1600182 | T37: =37000/1.73/SQRT(POWER((G37+Q37),2)+P37*P37) -> 2433.7186 | U37: =37000/2/SQRT(P37*P37+POWER((H37+Q37),2)) -> 2019.6466 | V37: 1 | W37: ТМН 6300/35 | X37: 6.3 | Y37: 11 | Z37: 35 | AA37: 6.3 | AB37: 8.01 | AC37: 103,9/577,3 | AE37: =AB37/100*Z37*Z37/X37 -> 15.575 | AF37: =SQRT(POWER(P37,2)+POWER(Q37+AE37+G37,2)) -> 24.176872 | AG37: =SQRT(POWER(P37,2)+POWER(Q37+AE37+H37,2)) -> 24.559515 | AH37: =SQRT(POWER((AE37+Q37+G37),2)+POWER(P37,2))*POWER(6.3/Z37,2) -> 0.78333065 | AI37: =SQRT(POWER((H37+Q37+AE37),2)+POWER(P37,2))*POWER(6.3/Z37,2) -> 0.79572828 | AJ37: =37000/1.73/SQRT(POWER((G37+Q37+AE37),2)+P37*P37) -> 884.61747 | AK37: =37000/2/SQRT(POWER((H37+Q37+AE37),2)+P37*P37) -> 753.27221 | AL37: =AK37/1.2 -> 627.72684 | AM37: =AK37/1.5 -> 502.18147 | AN37: =6300/(1.73*AH37) -> 4648.8906 | AO37: =SUM(6300/(2*AI37)) -> 3958.6377
A38: 1 | D38: 3.4 | E38: А | F38: Мартыновская | G38: =G16 -> 4.8982573 | H38: =H16 -> 5.2312064 | J38: 8.99 | P38: =0.314*I38+0.249*J38+0.195*M38+0.159*N38+0.06*O38 -> 2.23851 | Q38: =0.4*SUM(I38:O38) -> 3.596 | R38: =SQRT(POWER(P38,2)+POWER(Q38+G38,2)) -> 8.7842663 | S38: =SQRT(POWER(P38,2)+POWER(Q38+H38,2)) -> 9.1066185 | T38: =37000/1.73/SQRT(POWER((G38+Q38),2)+P38*P38) -> 2434.7262 | U38: =37000/2/SQRT(P38*P38+POWER((H38+Q38),2)) -> 2031.4895 | V38: 2 | W38: ТМН 6300/35 | X38: 6.3 | Y38: 11 | Z38: 35 | AA38: 6.3 | AB38: 8.01 | AC38: 103,9/577,3 | AE38: =AB38/100*Z38*Z38/X38 -> 15.575 | AF38: =SQRT(POWER(P38,2)+POWER(Q38+AE38+G38,2)) -> 24.173127 | AG38: =SQRT(POWER(P38,2)+POWER(Q38+AE38+H38,2)) -> 24.504665 | AH38: =SQRT(POWER((AE38+Q38+G38),2)+POWER(P38,2))*POWER(6.3/Z38,2) -> 0.78320932 | AI38: =SQRT(POWER((H38+Q38+AE38),2)+POWER(P38,2))*POWER(6.3/Z38,2) -> 0.79395114 | AJ38: =37000/1.73/SQRT(POWER((G38+Q38+AE38),2)+P38*P38) -> 884.75451 | AK38: =37000/2/SQRT(POWER((H38+Q38+AE38),2)+P38*P38) -> 754.95829 | AL38: =AK38/1.2 -> 629.13191 | AM38: =AK38/1.5 -> 503.30553 | AN38: =6300/(1.73*AH38) -> 4649.6108 | AO38: =SUM(6300/(2*AI38)) -> 3967.4985
A39: 1 | B39: Куст-120 | C39: ST-7 | D39: 5.6 | E39: А | F39: Кирьяновская | G39: 2.55 | H39: 5.42 | J39: 15.33 | P39: =0.314*I39+0.249*J39+0.195*M39+0.159*N39+0.06*O39 -> 3.81717 | Q39: =0.4*SUM(I39:O39) -> 6.132 | R39: =SQRT(POWER(P39,2)+POWER(Q39+G39,2)) -> 9.4840872 | S39: =SQRT(POWER(P39,2)+POWER(Q39+H39,2)) -> 12.166326 | T39: =37000/1.73/SQRT(POWER((G39+Q39),2)+P39*P39) -> 2255.0703 | U39: =37000/2/SQRT(P39*P39+POWER((H39+Q39),2)) -> 1520.5905 | V39: 1 | W39: TONb 4000/35 | X39: 4 | Y39: 11 | Z39: 35 | AA39: 6.3 | AB39: 6.23 | AC39: 66/367 | AD39: 5 | AE39: =AB39/100*Z39*Z39/X39 -> 19.079375 | AF39: =SQRT(POWER(P39,2)+POWER(Q39+AE39+G39,2)) -> 28.022575 | AG39: =SQRT(POWER(P39,2)+POWER(Q39+AE39+H39,2)) -> 30.8683 | AH39: =SQRT(POWER((AE39+Q39+G39),2)+POWER(P39,2))*POWER(6.3/Z39,2) -> 0.90793144 | AI39: =SQRT(POWER((H39+Q39+AE39),2)+POWER(P39,2))*POWER(6.3/Z39,2) -> 1.0001329 | AJ39: =37000/1.73/SQRT(POWER((G39+Q39+AE39),2)+P39*P39) -> 763.21619 | AK39: =37000/2/SQRT(POWER((H39+Q39+AE39),2)+P39*P39) -> 599.32035 | AL39: =AK39/1.2 -> 499.43362 | AM39: =AK39/1.5 -> 399.5469 | AN39: =6300/(1.73*AH39) -> 4010.8959 | AO39: =SUM(6300/(2*AI39)) -> 3149.5814
A40: 1 | D40: 5.6 | E40: А | F40: Кирьяновская | G40: 2.55 | H40: 5.42 | J40: 15.33 | P40: =0.314*I40+0.249*J40+0.195*M40+0.159*N40+0.06*O40 -> 3.81717 | Q40: =0.4*SUM(I40:O40) -> 6.132 | R40: =SQRT(POWER(P40,2)+POWER(Q40+G40,2)) -> 9.4840872 | S40: =SQRT(POWER(P40,2)+POWER(Q40+H40,2)) -> 12.166326 | T40: =37000/1.73/SQRT(POWER((G40+Q40),2)+P40*P40) -> 2255.0703 | U40: =37000/2/SQRT(P40*P40+POWER((H40+Q40),2)) -> 1520.5905 | V40: 2 | W40: TONb 4000/35 | X40: 4 | Y40: 11 | Z40: 35 | AA40: 6.3 | AB40: 6.23 | AC40: 66/367 | AD40: 5 | AE40: =AB40/100*Z40*Z40/X40 -> 19.079375 | AF40: =SQRT(POWER(P40,2)+POWER(Q40+AE40+G40,2)) -> 28.022575 | AG40: =SQRT(POWER(P40,2)+POWER(Q40+AE40+H40,2)) -> 30.8683 | AH40: =SQRT(POWER((AE40+Q40+G40),2)+POWER(P40,2))*POWER(6.3/Z40,2) -> 0.90793144 | AI40: =SQRT(POWER((H40+Q40+AE40),2)+POWER(P40,2))*POWER(6.3/Z40,2) -> 1.0001329 | AJ40: =37000/1.73/SQRT(POWER((G40+Q40+AE40),2)+P40*P40) -> 763.21619 | AK40: =37000/2/SQRT(POWER((H40+Q40+AE40),2)+P40*P40) -> 599.32035 | AL40: =AK40/1.2 -> 499.43362 | AM40: =AK40/1.5 -> 399.5469 | AN40: =6300/(1.73*AH40) -> 4010.8959 | AO40: =SUM(6300/(2*AI40)) -> 3149.5814
...

Sheet СР1
A1: Реактансы ПС 35/6кВ СР-1
A2: СР | B2: Наименование ПС 35/6кВ | C2: Тип ПС | D2: №Ф-35кВ | E2: Режим | F2: Головная ПС | G2: Реактансы на с.ш.35кВ ПС 110/35/6кВ | I2: Длина ВЛ-35кВ | P2: Хвл-35кВ | R2: Реактансы на ЛР 35кВ ПС 35/6кВ | T2: Токи на с.ш.35кВ ПС 35/6кВ до трансф. | V2: № тр-ра | W2: Тип | X2: S | Y2: Груп Соед | Z2: U ВН | AA2: U HН | AB2: Uкз | AC2: Iвн/Iнн | AD2: РПН | AE2: Хтмак | AF2: Реактансы на с.ш.35кВ ПС 35/6кВ | AH2: Реактансы на с.ш.6кВ ПС 35/6кВ | AJ2: Токи на с.ш.6кВ ПС 35/6кВ после трансф., приведенные к стороне 35кВ | AL2: Кч=1.2 | AM2: Кч=1.5 | AN2: Токи на с.ш.6кВ ПС 35/6кВ после трансф., приведенные к стороне 6,3кВ
G3: Хсмакc | H3: Хсмин | I3: АС-95 | J3: АС-120 | K3: 3ПвВнГ-ХЛ 1х50 | L3: АПвП 300 | M3: АС-150 | N3: АС-185 | O3: АС-500 | R3: Хмакс | S3: Хмин | T3: Iмакс | U3: Iмин | AF3: Хмакс | AG3: Хмин | AH3: Хмакс | AI3: Хмин | AJ3: Iмакс | AK3: Iмин | AN3: Iмакс | AO3: Iмин
G4: Ом | H4: Ом | I4: км | J4: км | K4: км | L4: км | M4: км | N4: км | O4: км | P4: Ом | Q4: Ом | R4: Ом | S4: Ом | T4: А | U4: А | X4: МВА | Z4: кВ | AA4: кВ | AB4: % | AC4: А | AD4: % | AE4: Ом | AF4: Ом | AG4: Ом | AH4: Ом | AI4: Ом | AJ4: А | AK4: А | AL4: А | AM4: А | AN4: А | AO4: А
A5: 1 | B5: ДНС-2В | C5: К-47 | D5: 5.6 | E5: Н | F5: Кирьяновская | G5: 2.55 | H5: 5.42 | J5: 4.53 | P5: =0.314*I5+0.249*J5+0.195*M5+0.159*N5+0.06*O5 -> 1.12797 | Q5: =0.4*SUM(I5:O5) -> 1.812 | R5: =SQRT(POWER(P5,2)+POWER(Q5+G5,2)) -> 4.5054811 | S5: =SQRT(POWER(P5,2)+POWER(Q5+H5,2)) -> 7.3194358 | T5: =37000/1.73/SQRT(POWER((G5+Q5),2)+P5*P5) -> 4746.9477 | U5: =37000/2/SQRT(P5*P5+POWER((H5+Q5),2)) -> 2527.5172 | V5: 1 | W5: TМН-4000/35 | X5: 4 | Y5: 11 | Z5: 35 | AA5: 6.3 | AB5: 7.67 | AC5: 66/366 | AD5: 9 | AE5: =AB5/100*Z5*Z5/X5 -> 23.489375 | AF5: =SQRT(POWER(P5,2)+POWER(Q5+AE5+G5,2)) -> 27.874207 | AG5: =SQRT(POWER(P5,2)+POWER(Q5+AE5+H5,2)) -> 30.742075 | AH5: =SQRT(POWER((AE5+Q5+G5),2)+POWER(P5,2))*POWER(6.3/Z5,2) -> 0.9031243 | AI5: =SQRT(POWER((H5+Q5+AE5),2)+POWER(P5,2))*POWER(6.3/Z5,2) -> 0.99604324 | AJ5: =37000/1.73/SQRT(POWER((G5+Q5+AE5),2)+P5*P5) -> 767.27863 | AK5: =37000/2/SQRT(POWER((H5+Q5+AE5),2)+P5*P5) -> 601.7811 | AL5: =AK5/1.2 -> 501.48425 | AM5: =AK5/1.5 -> 401.1874 | AN5: =6300/(1.73*AH5) -> 4032.2451 | AO5: =SUM(6300/(2*AI5)) -> 3162.5133
A6: 1 | D6: 5.6 | E6: Н | F6: Кирьяновская | G6: 2.55 | H6: 5.42 | J6: 4.53 | P6: =0.314*I6+0.249*J6+0.195*M6+0.159*N6+0.06*O6 -> 1.12797 | Q6: =0.4*SUM(I6:O6) -> 1.812 | R6: =SQRT(POWER(P6,2)+POWER(Q6+G6,2)) -> 4.5054811 | S6: =SQRT(POWER(P6,2)+POWER(Q6+H6,2)) -> 7.3194358 | T6: =37000/1.73/SQRT(POWER((G6+Q6),2)+P6*P6) -> 4746.9477 | U6: =37000/2/SQRT(P6*P6+POWER((H6+Q6),2)) -> 2527.5172 | V6: 2 | W6: TМН-4000/35 | X6: 4 | Y6: 11 | Z6: 35 | AA6: 6.3 | AB6: 7.6 | AC6: 66/366 | AD6: 12 | AE6: =AB6/100*Z6*Z6/X6 -> 23.275 | AF6: =SQRT(POWER(P6,2)+POWER(Q6+AE6+G6,2)) -> 27.660009 | AG6: =SQRT(POWER(P6,2)+POWER(Q6+AE6+H6,2)) -> 30.527846 | AH6: =SQRT(POWER((AE6+Q6+G6),2)+POWER(P6,2))*POWER(6.3/Z6,2) -> 0.89618428 | AI6: =SQRT(POWER((H6+Q6+AE6),2)+POWER(P6,2))*POWER(6.3/Z6,2) -> 0.9891022 | AJ6: =37000/1.73/SQRT(POWER((G6+Q6+AE6),2)+P6*P6) -> 773.22041 | AK6: =37000/2/SQRT(POWER((H6+Q6+AE6),2)+P6*P6) -> 606.00411 | AL6: =AK6/1.2 -> 505.00343 | AM6: =AK6/1.5 -> 404.00274 | AN6: =6300/(1.73*AH6) -> 4063.4706 | AO6: =SUM(6300/(2*AI6)) -> 3184.7063
A7: 1 | B7: КНС-4В | C7: К-47 | D7: 5.6 | E7: Н | F7: Кирьяновская | G7: 2.55 | H7: 5.42 | J7: 0.35 | P7: =0.314*I7+0.249*J7+0.195*M7+0.159*N7+0.06*O7 -> 0.08715 | Q7: =0.4*SUM(I7:O7) -> 0.14 | R7: =SQRT(POWER(P7,2)+POWER(Q7+G7,2)) -> 2.6914114 | S7: =SQRT(POWER(P7,2)+POWER(Q7+H7,2)) -> 5.560683 | T7: =37000/1.73/SQRT(POWER((G7+Q7),2)+P7*P7) -> 7946.4936 | U7: =37000/2/SQRT(P7*P7+POWER((H7+Q7),2)) -> 3326.9295 | V7: 1 | W7: ТМН 6300/35 | X7: 6.3 | Y7: 11 | Z7: 35 | AA7: 6.3 | AB7: 7.82 | AC7: 103,9/577,3 | AE7: =AB7/100*Z7*Z7/X7 -> 15.205556 | AF7: =SQRT(POWER(P7,2)+POWER(Q7+AE7+G7,2)) -> 17.895768 | AG7: =SQRT(POWER(P7,2)+POWER(Q7+AE7+H7,2)) -> 20.765738 | AH7: =SQRT(POWER((AE7+Q7+G7),2)+POWER(P7,2))*POWER(6.3/Z7,2) -> 0.57982288 | AI7: =SQRT(POWER((H7+Q7+AE7),2)+POWER(P7,2))*POWER(6.3/Z7,2) -> 0.67280993 | AJ7: =37000/1.73/SQRT(POWER((G7+Q7+AE7),2)+P7*P7) -> 1195.1029 | AK7: =37000/2/SQRT(POWER((H7+Q7+AE7),2)+P7*P7) -> 890.89054 | AL7: =AK7/1.2 -> 742.40879 | AM7: =AK7/1.5 -> 593.92703 | AN7: =6300/(1.73*AH7) -> 6280.5706 | AO7: =SUM(6300/(2*AI7)) -> 4681.8572
A8: 1 | D8: 5.6 | E8: Н | F8: Кирьяновская | G8: 2.55 | H8: 5.42 | J8: 0.35 | P8: =0.314*I8+0.249*J8+0.195*M8+0.159*N8+0.06*O8 -> 0.08715 | Q8: =0.4*SUM(I8:O8) -> 0.14 | R8: =SQRT(POWER(P8,2)+POWER(Q8+G8,2)) -> 2.6914114 | S8: =SQRT(POWER(P8,2)+POWER(Q8+H8,2)) -> 5.560683 | T8: =37000/1.73/SQRT(POWER((G8+Q8),2)+P8*P8) -> 7946.4936 | U8: =37000/2/SQRT(P8*P8+POWER((H8+Q8),2)) -> 3326.9295 | V8: 2 | W8: ТМН 6300/35 | X8: 6.3 | Y8: 11 | Z8: 35 | AA8: 6.3 | AB8: 7.94 | AC8: 103,9/577,3 | AE8: =AB8/100*Z8*Z8/X8 -> 15.438889 | AF8: =SQRT(POWER(P8,2)+POWER(Q8+AE8+G8,2)) -> 18.129098 | AG8: =SQRT(POWER(P8,2)+POWER(Q8+AE8+H8,2)) -> 20.99907 | AH8: =SQRT(POWER((AE8+Q8+G8),2)+POWER(P8,2))*POWER(6.3/Z8,2) -> 0.58738279 | AI8: =SQRT(POWER((H8+Q8+AE8),2)+POWER(P8,2))*POWER(6.3/Z8,2) -> 0.68036986 | AJ8: =37000/1.73/SQRT(POWER((G8+Q8+AE8),2)+P8*P8) -> 1179.7213 | AK8: =37000/2/SQRT(POWER((H8+Q8+AE8),2)+P8*P8) -> 880.99141 | AL8: =AK8/1.2 -> 734.15951 | AM8: =AK8/1.5 -> 587.3276 | AN8: =6300/(1.73*AH8) -> 6199.7365 | AO8: =SUM(6300/(2*AI8)) -> 4629.8347
A9: 1 | B9: КНС-5В | C9: К-47 | D9: 4.6 | E9: Н | F9: Ватинская | G9: 4.13 | H9: 6.96 | J9: 8.2 | P9: =0.314*I9+0.249*J9+0.195*M9+0.159*N9+0.06*O9 -> 2.0418 | Q9: =0.4*SUM(I9:O9) -> 3.28 | R9: =SQRT(POWER(P9,2)+POWER(Q9+G9,2)) -> 7.6861595 | S9: =SQRT(POWER(P9,2)+POWER(Q9+H9,2)) -> 10.441578 | T9: =37000/1.73/SQRT(POWER((G9+Q9),2)+P9*P9) -> 2782.5708 | U9: =37000/2/SQRT(P9*P9+POWER((H9+Q9),2)) -> 1771.7629 | V9: 1 | W9: ТМН 6300/35 | X9: 6.3 | Y9: 11 | Z9: 35 | AA9: 6.3 | AB9: 7.94 | AC9: 103,9/577,3 | AD9: 5 | AE9: =AB9/100*Z9*Z9/X9 -> 15.438889 | AF9: =SQRT(POWER(P9,2)+POWER(Q9+AE9+G9,2)) -> 22.939936 | AG9: =SQRT(POWER(P9,2)+POWER(Q9+AE9+H9,2)) -> 25.759936 | AH9: =SQRT(POWER((AE9+Q9+G9),2)+POWER(P9,2))*POWER(6.3/Z9,2) -> 0.74325393 | AI9: =SQRT(POWER((H9+Q9+AE9),2)+POWER(P9,2))*POWER(6.3/Z9,2) -> 0.83462191 | AJ9: =37000/1.73/SQRT(POWER((G9+Q9+AE9),2)+P9*P9) -> 932.3166 | AK9: =37000/2/SQRT(POWER((H9+Q9+AE9),2)+P9*P9) -> 718.1695 | AL9: =AK9/1.2 -> 598.47458 | AM9: =AK9/1.5 -> 478.77966 | AN9: =6300/(1.73*AH9) -> 4899.5617 | AO9: =SUM(6300/(2*AI9)) -> 3774.164
A10: 1 | D10: 4.6 | E10: Н | F10: Ватинская | G10: 4.13 | H10: 6.96 | J10: 8.2 | P10: =0.314*I10+0.249*J10+0.195*M10+0.159*N10+0.06*O10 -> 2.0418 | Q10: =0.4*SUM(I10:O10) -> 3.28 | R10: =SQRT(POWER(P10,2)+POWER(Q10+G10,2)) -> 7.6861595 | S10: =SQRT(POWER(P10,2)+POWER(Q10+H10,2)) -> 10.441578 | T10: =37000/1.73/SQRT(POWER((G10+Q10),2)+P10*P10) -> 2782.5708 | U10: =37000/2/SQRT(P10*P10+POWER((H10+Q10),2)) -> 1771.7629 | V10: 2 | W10: ТМН 6300/35 | X10: 6.3 | Y10: 11 | Z10: 35 | AA10: 6.3 | AB10: 7.96 | AC10: 103,9/577,3 | AD10: 5 | AE10: =AB10/100*Z10*Z10/X10 -> 15.477778 | AF10: =SQRT(POWER(P10,2)+POWER(Q10+AE10+G10,2)) -> 22.978671 | AG10: =SQRT(POWER(P10,2)+POWER(Q10+AE10+H10,2)) -> 25.798702 | AH10: =SQRT(POWER((AE10+Q10+G10),2)+POWER(P10,2))*POWER(6.3/Z10,2) -> 0.74450894 | AI10: =SQRT(POWER((H10+Q10+AE10),2)+POWER(P10,2))*POWER(6.3/Z10,2) -> 0.83587795 | AJ10: =37000/1.73/SQRT(POWER((G10+Q10+AE10),2)+P10*P10) -> 930.74501 | AK10: =37000/2/SQRT(POWER((H10+Q10+AE10),2)+P10*P10) -> 717.09033 | AL10: =AK10/1.2 -> 597.57528 | AM10: =AK10/1.5 -> 478.06022 | AN10: =6300/(1.73*AH10) -> 4891.3026 | AO10: =SUM(6300/(2*AI10)) -> 3768.4927
A11: 1 | B11: КНС-8В | C11: К-47 | D11: 5.6 | E11: Н | F11: Кирьяновская | G11: 2.55 | H11: 5.42 | J11: 4 | P11: =0.314*I11+0.249*J11+0.195*M11+0.159*N11+0.06*O11 -> 0.996 | Q11: =0.4*SUM(I11:O11) -> 1.6 | R11: =SQRT(POWER(P11,2)+POWER(Q11+G11,2)) -> 4.2678468 | S11: =SQRT(POWER(P11,2)+POWER(Q11+H11,2)) -> 7.0903044 | T11: =37000/1.73/SQRT(POWER((G11+Q11),2)+P11*P11) -> 5011.2585 | U11: =37000/2/SQRT(P11*P11+POWER((H11+Q11),2)) -> 2609.1969 | V11: 1 | W11: ТМН 6300/35 | X11: 6.3 | Y11: 11 | Z11: 35 | AA11: 6.3 | AB11: 7.41 | AC11: 104/577 | AD11: 12 | AE11: =AB11/100*Z11*Z11/X11 -> 14.408333 | AF11: =SQRT(POWER(P11,2)+POWER(Q11+AE11+G11,2)) -> 18.585041 | AG11: =SQRT(POWER(P11,2)+POWER(Q11+AE11+H11,2)) -> 21.451468 | AH11: =SQRT(POWER((AE11+Q11+G11),2)+POWER(P11,2))*POWER(6.3/Z11,2) -> 0.60215533 | AI11: =SQRT(POWER((H11+Q11+AE11),2)+POWER(P11,2))*POWER(6.3/Z11,2) -> 0.69502757 | AJ11: =37000/1.73/SQRT(POWER((G11+Q11+AE11),2)+P11*P11) -> 1150.7794 | AK11: =37000/2/SQRT(POWER((H11+Q11+AE11),2)+P11*P11) -> 862.41183 | AL11: =AK11/1.2 -> 718.67653 | AM11: =AK11/1.5 -> 574.94122 | AN11: =6300/(1.73*AH11) -> 6047.6397 | AO11: =SUM(6300/(2*AI11)) -> 4532.1943
A12: 1 | D12: 5.6 | E12: Н | F12: Кирьяновская | G12: 2.55 | H12: 5.42 | J12: 4 | P12: =0.314*I12+0.249*J12+0.195*M12+0.159*N12+0.06*O12 -> 0.996 | Q12: =0.4*SUM(I12:O12) -> 1.6 | R12: =SQRT(POWER(P12,2)+POWER(Q12+G12,2)) -> 4.2678468 | S12: =SQRT(POWER(P12,2)+POWER(Q12+H12,2)) -> 7.0903044 | T12: =37000/1.73/SQRT(POWER((G12+Q12),2)+P12*P12) -> 5011.2585 | U12: =37000/2/SQRT(P12*P12+POWER((H12+Q12),2)) -> 2609.1969 | V12: 2 | W12: ТМН 6300/35 | X12: 6.3 | Y12: 11 | Z12: 35 | AA12: 6.3 | AB12: 8.02 | AC12: 104/577 | AD12: 12 | AE12: =AB12/100*Z12*Z12/X12 -> 15.594444 | AF12: =SQRT(POWER(P12,2)+POWER(Q12+AE12+G12,2)) -> 19.76955 | AG12: =SQRT(POWER(P12,2)+POWER(Q12+AE12+H12,2)) -> 22.636367 | AH12: =SQRT(POWER((AE12+Q12+G12),2)+POWER(P12,2))*POWER(6.3/Z12,2) -> 0.64053342 | AI12: =SQRT(POWER((H12+Q12+AE12),2)+POWER(P12,2))*POWER(6.3/Z12,2) -> 0.73341829 | AJ12: =37000/1.73/SQRT(POWER((G12+Q12+AE12),2)+P12*P12) -> 1081.8295 | AK12: =37000/2/SQRT(POWER((H12+Q12+AE12),2)+P12*P12) -> 817.26895 | AL12: =AK12/1.2 -> 681.05746 | AM12: =AK12/1.5 -> 544.84597 | AN12: =6300/(1.73*AH12) -> 5685.2904 | AO12: =SUM(6300/(2*AI12)) -> 4294.957
A13: 1 | B13: Куст-47 новая | C13: АльянсЭлектро | D13: 4.6 | E13: Н | F13: Ватинская | G13: 4.13 | H13: 6.96 | J13: 8.1 | P13: =0.314*I13+0.249*J13+0.195*M13+0.159*N13+0.06*O13 -> 2.0169 | Q13: =0.4*SUM(I13:O13) -> 3.24 | R13: =SQRT(POWER(P13,2)+POWER(Q13+G13,2)) -> 7.6409938 | S13: =SQRT(POWER(P13,2)+POWER(Q13+H13,2)) -> 10.397494 | T13: =37000/1.73/SQRT(POWER((G13+Q13),2)+P13*P13) -> 2799.0185 | U13: =37000/2/SQRT(P13*P13+POWER((H13+Q13),2)) -> 1779.2749 | V13: 1 | W13: 6300/35 | X13: 6.3 | Y13: 11 | Z13: 35 | AA13: 6.3 | AB13: 7.92 | AC13: 66/367 | AD13: 5 | AE13: =AB13/100*Z13*Z13/X13 -> 15.4 | AF13: =SQRT(POWER(P13,2)+POWER(Q13+AE13+G13,2)) -> 22.859151 | AG13: =SQRT(POWER(P13,2)+POWER(Q13+AE13+H13,2)) -> 25.679328 | AH13: =SQRT(POWER((AE13+Q13+G13),2)+POWER(P13,2))*POWER(6.3/Z13,2) -> 0.74063649 | AI13: =SQRT(POWER((H13+Q13+AE13),2)+POWER(P13,2))*POWER(6.3/Z13,2) -> 0.83201023 | AJ13: =37000/1.73/SQRT(POWER((G13+Q13+AE13),2)+P13*P13) -> 935.61144 | AK13: =37000/2/SQRT(POWER((H13+Q13+AE13),2)+P13*P13) -> 720.42384 | AL13: =AK13/1.2 -> 600.3532 | AM13: =AK13/1.5 -> 480.28256 | AN13: =6300/(1.73*AH13) -> 4916.8769 | AO13: =SUM(6300/(2*AI13)) -> 3786.0112
A14: 1 | D14: 4.6 | E14: Н | F14: Ватинская | G14: 4.13 | H14: 6.96 | J14: 8.1 | P14: =0.314*I14+0.249*J14+0.195*M14+0.159*N14+0.06*O14 -> 2.0169 | Q14: =0.4*SUM(I14:O14) -> 3.24 | R14: =SQRT(POWER(P14,2)+POWER(Q14+G14,2)) -> 7.6409938 | S14: =SQRT(POWER(P14,2)+POWER(Q14+H14,2)) -> 10.397494 | T14: =37000/1.73/SQRT(POWER((G14+Q14),2)+P14*P14) -> 2799.0185 | U14: =37000/2/SQRT(P14*P14+POWER((H14+Q14),2)) -> 1779.2749 | V14: 2 | W14: 6300/35 | X14: 6.3 | Y14: 11 | Z14: 35 | AA14: 6.3 | AB14: 8.1 | AC14: 66/367 | AD14: 5 | AE14: =AB14/100*Z14*Z14/X14 -> 15.75 | AF14: =SQRT(POWER(P14,2)+POWER(Q14+AE14+G14,2)) -> 23.207807 | AG14: =SQRT(POWER(P14,2)+POWER(Q14+AE14+H14,2)) -> 26.028261 | AH14: =SQRT(POWER((AE14+Q14+G14),2)+POWER(P14,2))*POWER(6.3/Z14,2) -> 0.75193293 | AI14: =SQRT(POWER((H14+Q14+AE14),2)+POWER(P14,2))*POWER(6.3/Z14,2) -> 0.84331567 | AJ14: =37000/1.73/SQRT(POWER((G14+Q14+AE14),2)+P14*P14) -> 921.55556 | AK14: =37000/2/SQRT(POWER((H14+Q14+AE14),2)+P14*P14) -> 710.76588 | AL14: =AK14/1.2 -> 592.3049 | AM14: =AK14/1.5 -> 473.84392 | AN14: =6300/(1.73*AH14) -> 4843.0097 | AO14: =SUM(6300/(2*AI14)) -> 3735.2561
A15: 1 | B15: Куст-53 | C15: К-59 | D15: 1.2 | E15: Н | F15: Мартыновская | G15: =Мартыновская!G15 -> 4.9020181 | H15: =Мартыновская!H15 -> 5.2862861 | J15: 6.21 | P15: =0.314*I15+0.249*J15+0.195*M15+0.159*N15+0.06*O15 -> 1.54629 | Q15: =0.4*SUM(I15:O15) -> 2.484 | R15: =SQRT(POWER(P15,2)+POWER(Q15+G15,2)) -> 7.5461432 | S15: =SQRT(POWER(P15,2)+POWER(Q15+H15,2)) -> 7.9226485 | T15: =37000/1.73/SQRT(POWER((G15+Q15),2)+P15*P15) -> 2834.2006 | U15: =37000/2/SQRT(P15*P15+POWER((H15+Q15),2)) -> 2335.0777 | V15: 1 | W15: ТМН 6300/35 | X15: 6.3 | Y15: 11 | Z15: 35 | AA15: 6.3 | AB15: 8.01 | AC15: 103,9/577,3 | AE15: =AB15/100*Z15*Z15/X15 -> 15.575 | AF15: =SQRT(POWER(P15,2)+POWER(Q15+AE15+G15,2)) -> 23.013026 | AG15: =SQRT(POWER(P15,2)+POWER(Q15+AE15+H15,2)) -> 23.39644 | AH15: =SQRT(POWER((AE15+Q15+G15),2)+POWER(P15,2))*POWER(6.3/Z15,2) -> 0.74562204 | AI15: =SQRT(POWER((H15+Q15+AE15),2)+POWER(P15,2))*POWER(6.3/Z15,2) -> 0.75804465 | AJ15: =37000/1.73/SQRT(POWER((G15+Q15+AE15),2)+P15*P15) -> 929.35554 | AK15: =37000/2/SQRT(POWER((H15+Q15+AE15),2)+P15*P15) -> 790.71859 | AL15: =AK15/1.2 -> 658.93216 | AM15: =AK15/1.5 -> 527.14573 | AN15: =6300/(1.73*AH15) -> 4884.0006 | AO15: =SUM(6300/(2*AI15)) -> 4155.428
A16: 1 | D16: 1.2 | E16: Н | F16: Мартыновская | G16: =Мартыновская!G16 -> 4.8982573 | H16: =Мартыновская!H16 -> 5.2312064 | J16: 6.21 | P16: =0.314*I16+0.249*J16+0.195*M16+0.159*N16+0.06*O16 -> 1.54629 | Q16: =0.4*SUM(I16:O16) -> 2.484 | R16: =SQRT(POWER(P16,2)+POWER(Q16+G16,2)) -> 7.5424622 | S16: =SQRT(POWER(P16,2)+POWER(Q16+H16,2)) -> 7.8686354 | T16: =37000/1.73/SQRT(POWER((G16+Q16),2)+P16*P16) -> 2835.5837 | U16: =37000/2/SQRT(P16*P16+POWER((H16+Q16),2)) -> 2351.1065 | V16: 2 | W16: ТМН 6300/35 | X16: 6.3 | Y16: 11 | Z16: 35 | AA16: 6.3 | AB16: 8.01 | AC16: 103,9/577,3 | AE16: =AB16/100*Z16*Z16/X16 -> 15.575 | AF16: =SQRT(POWER(P16,2)+POWER(Q16+AE16+G16,2)) -> 23.009274 | AG16: =SQRT(POWER(P16,2)+POWER(Q16+AE16+H16,2)) -> 23.341481 | AH16: =SQRT(POWER((AE16+Q16+G16),2)+POWER(P16,2))*POWER(6.3/Z16,2) -> 0.74550047 | AI16: =SQRT(POWER((H16+Q16+AE16),2)+POWER(P16,2))*POWER(6.3/Z16,2) -> 0.75626398 | AJ16: =37000/1.73/SQRT(POWER((G16+Q16+AE16),2)+P16*P16) -> 929.5071 | AK16: =37000/2/SQRT(POWER((H16+Q16+AE16),2)+P16*P16) -> 792.58039 | AL16: =AK16/1.2 -> 660.48366 | AM16: =AK16/1.5 -> 528.38693 | AN16: =6300/(1.73*AH16) -> 4884.7971 | AO16: =SUM(6300/(2*AI16)) -> 4165.2123
A17: 1 | B17: Куст-120 | C17: ST-7 | D17: 4.6 | E17: Н | F17: Ватинская | G17: 4.13 | H17: 6.96 | J17: 12.9 | P17: =0.314*I17+0.249*J17+0.195*M17+0.159*N17+0.06*O17 -> 3.2121 | Q17: =0.4*SUM(I17:O17) -> 5.16 | R17: =SQRT(POWER(P17,2)+POWER(Q17+G17,2)) -> 9.8296331 | S17: =SQRT(POWER(P17,2)+POWER(Q17+H17,2)) -> 12.53842 | T17: =37000/1.73/SQRT(POWER((G17+Q17),2)+P17*P17) -> 2175.7967 | U17: =37000/2/SQRT(P17*P17+POWER((H17+Q17),2)) -> 1475.465 | V17: 1 | W17: TONb 4000/35 | X17: 4 | Y17: 11 | Z17: 35 | AA17: 6.3 | AB17: 6.23 | AC17: 66/367 | AD17: 5 | AE17: =AB17/100*Z17*Z17/X17 -> 19.079375 | AF17: =SQRT(POWER(P17,2)+POWER(Q17+AE17+G17,2)) -> 28.55064 | AG17: =SQRT(POWER(P17,2)+POWER(Q17+AE17+H17,2)) -> 31.364288 | AH17: =SQRT(POWER((AE17+Q17+G17),2)+POWER(P17,2))*POWER(6.3/Z17,2) -> 0.92504072 | AI17: =SQRT(POWER((H17+Q17+AE17),2)+POWER(P17,2))*POWER(6.3/Z17,2) -> 1.0162029 | AJ17: =37000/1.73/SQRT(POWER((G17+Q17+AE17),2)+P17*P17) -> 749.09997 | AK17: =37000/2/SQRT(POWER((H17+Q17+AE17),2)+P17*P17) -> 589.84281 | AL17: =AK17/1.2 -> 491.53567 | AM17: =AK17/1.5 -> 393.22854 | AN17: =6300/(1.73*AH17) -> 3936.7115 | AO17: =SUM(6300/(2*AI17)) -> 3099.7745
A18: 1 | D18: 4.6 | E18: Н | F18: Ватинская | G18: 4.13 | H18: 6.96 | J18: 12.9 | P18: =0.314*I18+0.249*J18+0.195*M18+0.159*N18+0.06*O18 -> 3.2121 | Q18: =0.4*SUM(I18:O18) -> 5.16 | R18: =SQRT(POWER(P18,2)+POWER(Q18+G18,2)) -> 9.8296331 | S18: =SQRT(POWER(P18,2)+POWER(Q18+H18,2)) -> 12.53842 | T18: =37000/1.73/SQRT(POWER((G18+Q18),2)+P18*P18) -> 2175.7967 | U18: =37000/2/SQRT(P18*P18+POWER((H18+Q18),2)) -> 1475.465 | V18: 2 | W18: TONb 4000/35 | X18: 4 | Y18: 11 | Z18: 35 | AA18: 6.3 | AB18: 6.23 | AC18: 66/367 | AD18: 5 | AE18: =AB18/100*Z18*Z18/X18 -> 19.079375 | AF18: =SQRT(POWER(P18,2)+POWER(Q18+AE18+G18,2)) -> 28.55064 | AG18: =SQRT(POWER(P18,2)+POWER(Q18+AE18+H18,2)) -> 31.364288 | AH18: =SQRT(POWER((AE18+Q18+G18),2)+POWER(P18,2))*POWER(6.3/Z18,2) -> 0.92504072 | AI18: =SQRT(POWER((H18+Q18+AE18),2)+POWER(P18,2))*POWER(6.3/Z18,2) -> 1.0162029 | AJ18: =37000/1.73/SQRT(POWER((G18+Q18+AE18),2)+P18*P18) -> 749.09997 | AK18: =37000/2/SQRT(POWER((H18+Q18+AE18),2)+P18*P18) -> 589.84281 | AL18: =AK18/1.2 -> 491.53567 | AM18: =AK18/1.5 -> 393.22854 | AN18: =6300/(1.73*AH18) -> 3936.7115 | AO18: =SUM(6300/(2*AI18)) -> 3099.7745
