Workbook

Sheet Расчет
A1: Сетевой район: | C1: 8 | H1: РАСЧЕТ ЗАЩИТЫ ЛИНИИ 6 кВ
A2: ПС/РУ: | B2: ПС 35/6кВ "Ачимовская-1"
A3: Присоединение: | C3: ф.6кВ №20
A4: Реактансы: | D4: Р | E4: max | F4: min | H4: Нагрузка на фидере 6кВ: | L4: S [кВА]
C5: 401 | D5: Н | E5: =VLOOKUP(C5,[1]Реактансы!$A$2:$D$450,3) -> 0.73 | F5: =VLOOKUP(C5,[1]Реактансы!$A$2:$D$450,4) -> 0.575 | I5: 250
D6: А | E6: =IF(VLOOKUP(C5,[1]Реактансы!$A$2:$K$450,10)>0,VLOOKUP(C5,[1]Реактансы!$A$2:$K$450,10),"---") -> --- | F6: =IF(VLOOKUP(C5,[1]Реактансы!$A$2:$K$450,11)>0,VLOOKUP(C5,[1]Реактансы!$A$2:$K$450,11),"---") -> ---
A8: Участок 1: | D8: Длина,км | E8: R, Ом | F8: X, Ом
A9: Провод | C9: 1 | D9: 1 | E9: =VLOOKUP(C9,[1]Провода!$A$1:$E$27,3) -> 1.14 | F9: =VLOOKUP(C9,[1]Провода!$A$1:$E$27,4) -> 0.4 | L9: =SUM(I4:K9) -> 250
A10: Кабель | C10: 1 | D10: 1 | E10: =VLOOKUP(C10,[1]Кабели!$A$1:$E$68,3) -> 3.1 | F10: =VLOOKUP(C10,[1]Кабели!$A$1:$E$68,4) -> 0.11 | I10: Iном.= | J10: =L9/10.38 -> 24.084778 | K10: (А)
A11: Участок 2: | D11: Длина,км | E11: R, Ом | F11: X, Ом | I11: 0,7Iн.= | J11: =0.7*J10 -> 16.859345 | K11: (А)
A12: Провод | C12: 1 | D12: 1 | E12: =VLOOKUP(C12,[1]Провода!$A$1:$E$27,3) -> 1.14 | F12: =VLOOKUP(C12,[1]Провода!$A$1:$E$27,4) -> 0.4 | I12: Iреал.= | J12: 22 | K12: (А)
A13: Кабель | C13: 1 | D13: 1 | E13: =VLOOKUP(C13,[1]Кабели!$A$1:$E$68,3) -> 3.1 | F13: =VLOOKUP(C13,[1]Кабели!$A$1:$E$68,4) -> 0.11
A14: Участок 3: | D14: Длина,км | E14: R, Ом | F14: X, Ом | H14: Реле тока | L14: К надеж.
A15: Провод | C15: 1 | D15: 1 | E15: =VLOOKUP(C15,[1]Провода!$A$1:$E$27,3) -> 1.14 | F15: =VLOOKUP(C15,[1]Провода!$A$1:$E$27,4) -> 0.4
A16: Кабель | C16: 1 | D16: 1 | E16: =VLOOKUP(C16,[1]Кабели!$A$1:$E$68,3) -> 3.1 | F16: =VLOOKUP(C16,[1]Кабели!$A$1:$E$68,4) -> 0.11 | K16: 6
A17: Участок 4: | D17: Длина,км | E17: R, Ом | F17: X, Ом
A18: Провод | C18: 1 | D18: 1 | E18: =VLOOKUP(C18,[1]Провода!$A$1:$E$27,3) -> 1.14 | F18: =VLOOKUP(C18,[1]Провода!$A$1:$E$27,4) -> 0.4
A19: Кабель | C19: 1 | D19: 1 | E19: =VLOOKUP(C19,[1]Кабели!$A$1:$E$68,3) -> 3.1 | F19: =VLOOKUP(C19,[1]Кабели!$A$1:$E$68,4) -> 0.11 | H19: Для тока намагничивания: | L19: =VLOOKUP(K16,[1]Реле!$A$1:$D$10,4) -> 3
A20: Длина линии до КЛ,км | D20: =SUM(D9:D19) -> 8 | H20: Для КЗ за трансформатором: | L20: =VLOOKUP(K16,[1]Реле!$A$1:$D$10,3) -> 1.15
A22: Ближайший мощный трансформатор | E22: X тр | H22: Значение тока:
H24: 3-х фазного КЗ за тр-ом: | K24: =IFERROR('1'!B44*L20,"---") -> 113.40293 | L24: =IFERROR('1'!P44*L20,"---") -> --- | M24: А
H25: от намагничивания: | K25: =J10*L19 -> 72.254335 | M25: А
D26: 2 | E26: =VLOOKUP(D26,[1]Трансформаторы!$A$1:$C$12,3) -> 9.68 | H26: МТО: | K26: 20 | M26: А
A27: Участок 1: | D27: Длина,км | E27: R, Ом | F27: X, Ом | H27: t,сек: | J27: 0
A28: Провод | C28: 1 | D28: 1 | E28: =VLOOKUP(C28,[1]Провода!$A$1:$E$27,3) -> 1.14 | F28: =VLOOKUP(C28,[1]Провода!$A$1:$E$27,4) -> 0.4 | H28: АПВ,сек: | J28: 15
A29: Кабель | C29: 1 | D29: 1 | E29: =VLOOKUP(C29,[1]Кабели!$A$1:$E$68,3) -> 3.1 | F29: =VLOOKUP(C29,[1]Кабели!$A$1:$E$68,4) -> 0.11 | H29: Значение тока:
A30: Участок 2: | D30: Длина,км | E30: R, Ом | F30: X, Ом
A31: Провод | C31: 1 | D31: 1 | E31: =VLOOKUP(C31,[1]Провода!$A$1:$E$27,3) -> 1.14 | F31: =VLOOKUP(C31,[1]Провода!$A$1:$E$27,4) -> 0.4 | H31: расчетного: | K31: =J11*1.5 -> 25.289017 | L31: А
A32: Кабель | C32: 1 | D32: 1 | E32: =VLOOKUP(C32,[1]Кабели!$A$1:$E$68,3) -> 3.1 | F32: =VLOOKUP(C32,[1]Кабели!$A$1:$E$68,4) -> 0.11 | H32: реального: | K32: =J12*1.5 -> 33 | L32: А
A33: Участок 3: | D33: Длина,км | E33: R, Ом | F33: X, Ом | H33: МТЗ: | K33: 20 | L33: А
A34: Провод | C34: 1 | D34: 1 | E34: =VLOOKUP(C34,[1]Провода!$A$1:$E$27,3) -> 1.14 | F34: =VLOOKUP(C34,[1]Провода!$A$1:$E$27,4) -> 0.4 | H34: t,сек: | J34: 0.5 | K34: =VLOOKUP(K16,[1]Реле!$A$1:$E$9,5) -> Кратности нет
A35: Кабель | C35: 1 | D35: 1 | E35: =VLOOKUP(C35,[1]Кабели!$A$1:$E$68,3) -> 3.1 | F35: =VLOOKUP(C35,[1]Кабели!$A$1:$E$68,4) -> 0.11 | H35: МТЗдоп: | K35: ='1'!D30 -> 61.335495 | L35: =IFERROR('1'!R30,"---") -> --- | M35: А
A36: Участок 4: | D36: Длина,км | E36: R, Ом | F36: X, Ом
A37: Провод | C37: 1 | D37: 1 | E37: =VLOOKUP(C37,[1]Провода!$A$1:$E$27,3) -> 1.14 | F37: =VLOOKUP(C37,[1]Провода!$A$1:$E$27,4) -> 0.4 | H37: 2-х ф. КЗ в КЛ: | K37: ='1'!B30 -> 92.003242 | L37: =IFERROR('1'!P30,"---") -> --- | M37: А
A38: Кабель | C38: 1 | D38: 1 | E38: =VLOOKUP(C38,[1]Кабели!$A$1:$E$68,3) -> 3.1 | F38: =VLOOKUP(C38,[1]Кабели!$A$1:$E$68,4) -> 0.11 | H38: Значение тока:
A39: Длина линии до трансф.,км | D39: =SUM(D28:D38) -> 8 | H39: расчетного: | L39: А
H40: ЗОЗЗ: | L40: А
H41: t,сек:
H42: Действие защиты: | K42: на сигнал
H43: Трансформатор тока: | K43: 300 | L43: / 5
...

Sheet Телефонограмма
A1: ТЕЛЕФОНОГРАММА
D2: № | E2: =Расчет!B49 -> 211
D3: от | E3: =Расчет!D49 -> 46085
A5: Начальнику сетевого района № | D5: =Расчет!C1 -> 8 | E5: =VLOOKUP(Расчет!C1,[1]СР!$A$2:$C$12,3) -> Баркову А.А.
A6: от начальника службы РЗА Перемитина А.В.
A8: Подстанция/РУ: | C8: =Расчет!B2 -> ПС 35/6кВ "Ачимовская-1"
A9: Присоединение: | C9: =Расчет!C3 -> ф.6кВ №20
A11: Первичный номинальный ток трансформаторов тока (А): | I11: =Расчет!K43 -> 300
A12: Вторичный номинальный ток трансформаторов тока (А): | I12: 5
A13: АПВ (с): | I13: =Расчет!J28 -> 15
A14: Токовая отсечка
A15: Тип реле защиты: | I15: =VLOOKUP(Расчет!$K$16,[1]Реле!$A$2:$F$10,6) -> цифровое
A16: Ток срабатывания защиты (А): | I16: =Расчет!K26 -> 20
A17: Ток срабатывания реле (А): | I17: =Расчет!K26/Расчет!K43*5 -> 0.33333333
A18: Время срабатывания (с): | I18: =Расчет!J27 -> 0
A20: Максимальная токовая защита
A21: Тип реле защиты: | I21: =VLOOKUP(Расчет!$K$16,[1]Реле!$A$2:$F$10,6) -> цифровое
A22: Ток срабатывания защиты (А): | I22: =Расчет!K33 -> 20
A23: Ток срабатывания реле (А): | I23: =Расчет!K33/Расчет!K43*5 -> 0.33333333
A24: Время срабатывания (с): | H24: =Расчет!J34 -> 0.5 | I24: =Расчет!K34 -> Кратности нет
A26: Защита от однофазных замыканий на землю (ЗОЗЗ)
A27: Ток срабатывания защиты (А): | I27: =Расчет!K40 -> 0
A28: Время срабатывания (с): | I28: =Расчет!J41 -> 0
A29: Действие защиты: | I29: =Расчет!K42 -> на сигнал
C30: =Расчет!M45 -> 0
A32: Примечание:
A35: Начальник РЗА: | D35: Перемитин А.В. | G35: Подпись: | H35: _________
A36: Вед.инженер РЗА: | D36: Медведева А.В. | G36: Подпись: | H36: _________
A37: Изменение согласовано "ФИО"
A38: Исполнитель: | D38: ____________ | G38: Подпись: | H38: _________
A39: Дата выполнения: | D39: ____________
A40: После изменения уставок отправить факсом подписанное исполнителем задание в службу РЗА

Sheet 1
A7: Длины: | H7: Для первой точки | L7: Итог | M7: Проверка
A8: 0L= | B8: =0*Расчет!D20 -> 0 | C8: км | M8: =IF(L9+L11+L13+L15=B9,TRUE,FALSE) -> TRUE
A9: 0,1L= | B9: =0.1*Расчет!D20 -> 0.8 | C9: км | H9: 1 | I9: =IF(Расчет!D9+Расчет!D10>=B9,B9,K9) -> 0.8 | J9: =IF(Расчет!D9+Расчет!D10=B9,B9,K9) -> 0.8 | K9: =IF(Расчет!D9+Расчет!D10<B9,Расчет!D9+Расчет!D10,I9) -> 0.8 | L9: =IF(K9<=0,0,K9) -> 0.8
A10: 0,2L= | B10: =0.2*Расчет!D20 -> 1.6 | C10: км
A11: 0,3L= | B11: =0.3*Расчет!D20 -> 2.4 | C11: км | H11: 2 | I11: =IF(Расчет!D12+Расчет!D13<=0,0,J11) -> 0 | J11: =IF(B9<=Расчет!D9+Расчет!D10,0,K11) -> 0 | K11: =IF(B9>=Расчет!D9+Расчет!D10+Расчет!D12+Расчет!D13,Расчет!D12+Расчет!D13,B9-(Расчет!D9+Расчет!D10)) -> -1.2 | L11: =IF(K11<=0,0,K11) -> 0
A12: 0,4L= | B12: =0.4*Расчет!D20 -> 3.2 | C12: км
A13: 0,5L= | B13: =0.5*Расчет!D20 -> 4 | C13: км | H13: 3 | I13: =IF(Расчет!D15+Расчет!D16<=0,0,J13) -> 0 | J13: =IF(B9<=Расчет!D9+Расчет!D10+Расчет!D12+Расчет!D13,0,K13) -> 0 | K13: =IF(B9>=Расчет!D9+Расчет!D10+Расчет!D12+Расчет!D13+Расчет!D15+Расчет!D16,Расчет!D15+Расчет!D16,B9-(Расчет!D9+Расчет!D10+Расчет!D12+Расчет!D13)) -> -3.2 | L13: =IF(K13<=0,0,K13) -> 0
A14: 0,6L= | B14: =0.6*Расчет!D20 -> 4.8 | C14: км
A15: 0,7L= | B15: =0.7*Расчет!D20 -> 5.6 | C15: км | H15: 4 | I15: =IF(Расчет!D18+Расчет!D19<=0,0,J15) -> 0 | J15: =IF(B9<=Расчет!D9+Расчет!D10+Расчет!D12+Расчет!D13+Расчет!D15+Расчет!D16,0,K15) -> 0 | K15: =IF(B9>=Расчет!D9+Расчет!D10+Расчет!D12+Расчет!D13+Расчет!D15+Расчет!D16+Расчет!D18+Расчет!D19,Расчет!D18+Расчет!D19,B9-(Расчет!D9+Расчет!D10+Расчет!D12+Расчет!D13+Расчет!D15+Расчет!D16)) -> -5.2 | L15: =IF(K15<=0,0,K15) -> 0
A16: 0,8L= | B16: =0.8*Расчет!D20 -> 6.4 | C16: км | H16: }{min | I16: суммар: | J16: =SQRT((SUMSQ(L9*(Расчет!E9+Расчет!E10)+L11*(Расчет!E12+Расчет!E13)+L13*(Расчет!E15+Расчет!E16)+L15*(Расчет!E18+Расчет!E19)))+(SUMSQ(Расчет!F5+L9*(Расчет!F9+Расчет!F10)+L11*(Расчет!F12+Расчет!F13)+L13*(Расчет!F15+Расчет!F16)+L15*(Расчет!F18+Расчет!F19)))) -> 3.5315652 | K16: Н
A17: 0,9L= | B17: =0.9*Расчет!D20 -> 7.2 | C17: км | J17: =IFERROR(SQRT((SUMSQ(L9*(Расчет!E9+Расчет!E10)+L11*(Расчет!E12+Расчет!E13)+L13*(Расчет!E15+Расчет!E16)+L15*(Расчет!E18+Расчет!E19)))+(SUMSQ(Расчет!F6+L9*(Расчет!F9+Расчет!F10)+L11*(Расчет!F12+Расчет!F13)+L13*(Расчет!F15+Расчет!F16)+L15*(Расчет!F18+Расчет!F19)))),"---") -> --- | K17: А
A18: L= | B18: =1*Расчет!D20 -> 8 | C18: км | H18: Для второй точки | L18: Итог | M18: Проверка
A19: Токи 2-х фазного КЗ на КЛ: | D19: с уч.Кчувств | M19: =IF(L20+L22+L24+L26=B10,TRUE,FALSE) -> TRUE | O19: Токи 2-х фазного КЗ на КЛ: | R19: с уч.Кчувств
A20: на с.ш.= | B20: =6300/(2*Расчет!F5) -> 5478.2609 | C20: А | D20: =B20/1.5 -> 3652.1739 | E20: А | H20: 1 | I20: =IF(Расчет!D9+Расчет!D10>=B10,B10,K20) -> 1.6 | J20: =IF(Расчет!D9+Расчет!D10=B10,B10,K20) -> 1.6 | K20: =IF(Расчет!D9+Расчет!D10<B10,Расчет!D9+Расчет!D10,I20) -> 1.6 | L20: =IF(K20<=0,0,K20) -> 1.6 | O20: на с.ш.= | P20: =IFERROR(6300/(2*Расчет!F6),NA()) -> #N/A | Q20: А | R20: =IFERROR(P20/1.5,NA()) -> #N/A | S20: А
A21: 0,1L= | B21: =6300/(2*J16) -> 891.95577 | C21: А | D21: =B21/1.5 -> 594.63718 | E21: А | O21: 0,1L= | P21: =IFERROR(6300/(2*J17),NA()) -> #N/A | Q21: А | R21: =IFERROR(P21/1.5,NA()) -> #N/A | S21: А
A22: 0,2L= | B22: =6300/(2*J27) -> 454.86458 | C22: А | D22: =B22/1.5 -> 303.24305 | E22: А | H22: 2 | I22: =IF(Расчет!D12+Расчет!D13<=0,0,J22) -> 0 | J22: =IF(B10<=Расчет!D9+Расчет!D10,0,K22) -> 0 | K22: =IF(B10>=Расчет!D9+Расчет!D10+Расчет!D12+Расчет!D13,Расчет!D12+Расчет!D13,B10-(Расчет!D9+Расчет!D10)) -> -0.4 | L22: =IF(K22<=0,0,K22) -> 0 | O22: 0,2L= | P22: =IFERROR(6300/(2*J28),NA()) -> #N/A | Q22: А | R22: =IFERROR(P22/1.5,NA()) -> #N/A | S22: А
A23: 0,3L= | B23: =6300/(2*J38) -> 304.82501 | C23: А | D23: =B23/1.5 -> 203.21667 | E23: А | O23: 0,3L= | P23: =IFERROR(6300/(2*J39),NA()) -> #N/A | Q23: А | R23: =IFERROR(P23/1.5,NA()) -> #N/A | S23: А
A24: 0,4L= | B24: =6300/(2*J49) -> 229.15214 | C24: А | D24: =B24/1.5 -> 152.76809 | E24: А | H24: 3 | I24: =IF(Расчет!D15+Расчет!D16<=0,0,J24) -> 0 | J24: =IF(B10<=Расчет!D9+Расчет!D10+Расчет!D12+Расчет!D13,0,K24) -> 0 | K24: =IF(B10>=Расчет!D9+Расчет!D10+Расчет!D12+Расчет!D13+Расчет!D15+Расчет!D16,Расчет!D15+Расчет!D16,B10-(Расчет!D9+Расчет!D10+Расчет!D12+Расчет!D13)) -> -2.4 | L24: =IF(K24<=0,0,K24) -> 0 | O24: 0,4L= | P24: =IFERROR(6300/(2*J50),NA()) -> #N/A | Q24: А | R24: =IFERROR(P24/1.5,NA()) -> #N/A | S24: А
A25: 0,5L= | B25: =6300/(2*J60) -> 183.562 | C25: А | D25: =B25/1.5 -> 122.37467 | E25: А | O25: 0,5L= | P25: =IFERROR(6300/(2*J61),NA()) -> #N/A | Q25: А | R25: =IFERROR(P25/1.5,NA()) -> #N/A | S25: А
A26: 0,6L= | B26: =6300/(2*J71) -> 153.09629 | C26: А | D26: =B26/1.5 -> 102.06419 | E26: А | H26: 4 | I26: =IF(Расчет!D18+Расчет!D19<=0,0,J26) -> 0 | J26: =IF(B10<=Расчет!D9+Расчет!D10+Расчет!D12+Расчет!D13+Расчет!D15+Расчет!D16,0,K26) -> 0 | K26: =IF(B10>=Расчет!D9+Расчет!D10+Расчет!D12+Расчет!D13+Расчет!D15+Расчет!D16+Расчет!D18+Расчет!D19,Расчет!D18+Расчет!D19,B10-(Расчет!D9+Расчет!D10+Расчет!D12+Расчет!D13+Расчет!D15+Расчет!D16)) -> -4.4 | L26: =IF(K26<=0,0,K26) -> 0 | O26: 0,6L= | P26: =IFERROR(6300/(2*J72),NA()) -> #N/A | Q26: А | R26: =IFERROR(P26/1.5,NA()) -> #N/A | S26: А
A27: 0,7L= | B27: =6300/(2*J82) -> 131.30138 | C27: А | D27: =B27/1.5 -> 87.534253 | E27: А | H27: }{min | I27: суммар: | J27: =SQRT((SUMSQ(L20*(Расчет!E9+Расчет!E10)+L22*(Расчет!E12+Расчет!E13)+L24*(Расчет!E15+Расчет!E16)+L26*(Расчет!E18+Расчет!E19)))+(SUMSQ(Расчет!F5+L20*(Расчет!F9+Расчет!F10)+L22*(Расчет!F12+Расчет!F13)+L24*(Расчет!F15+Расчет!F16)+L26*(Расчет!F18+Расчет!F19)))) -> 6.925138 | K27: Н | O27: 0,7L= | P27: =IFERROR(6300/(2*J83),NA()) -> #N/A | Q27: А | R27: =IFERROR(P27/1.5,NA()) -> #N/A | S27: А
A28: 0,8L= | B28: =6300/(2*J93) -> 114.93745 | C28: А | D28: =B28/1.5 -> 76.624966 | E28: А | J28: =IFERROR(SQRT((SUMSQ(L20*(Расчет!E9+Расчет!E10)+L22*(Расчет!E12+Расчет!E13)+L24*(Расчет!E15+Расчет!E16)+L26*(Расчет!E18+Расчет!E19)))+(SUMSQ(Расчет!F6+L20*(Расчет!F9+Расчет!F10)+L22*(Расчет!F12+Расчет!F13)+L24*(Расчет!F15+Расчет!F16)+L26*(Расчет!F18+Расчет!F19)))),"---") -> --- | K28: А | O28: 0,8L= | P28: =IFERROR(6300/(2*J94),NA()) -> #N/A | Q28: А | R28: =IFERROR(P28/1.5,NA()) -> #N/A | S28: А
A29: 0,9L= | B29: =6300/(2*J104) -> 102.19972 | C29: А | D29: =B29/1.5 -> 68.133148 | E29: А | H29: Для третьей точки | L29: Итог | M29: Проверка | O29: 0,9L= | P29: =IFERROR(6300/(2*J105),NA()) -> #N/A | Q29: А | R29: =IFERROR(P29/1.5,NA()) -> #N/A | S29: А
A30: L= | B30: =6300/(2*J115) -> 92.003242 | C30: А | D30: =B30/1.5 -> 61.335495 | E30: А | M30: =IF(L31+L33+L35+L37=B11,TRUE,FALSE) -> TRUE | O30: L= | P30: =IFERROR(6300/(2*J116),NA()) -> #N/A | Q30: А | R30: =IFERROR(P30/1.5,NA()) -> #N/A | S30: А
A31: МТЗдоп= | B31: =B30/1.5 -> 61.335495 | C31: А | H31: 1 | I31: =IF(Расчет!D9+Расчет!D10>=B11,B11,K31) -> 2 | J31: =IF(Расчет!D9+Расчет!D10=B11,B11,K31) -> 2 | K31: =IF(Расчет!D9+Расчет!D10<B11,Расчет!D9+Расчет!D10,I31) -> 2 | L31: =IF(K31<=0,0,K31) -> 2 | O31: МТЗдоп= | P31: =IFERROR(P30/1.5,"---") -> --- | Q31: А
A32: МТЗдоп= | B32: =B30/1.5 -> 61.335495 | C32: А | O32: МТЗдоп= | P32: =IFERROR(P30/1.5,"---") -> --- | Q32: А
A33: МТЗдоп= | B33: =B30/1.5 -> 61.335495 | C33: А | H33: 2 | I33: =IF(Расчет!D12+Расчет!D13<=0,0,J33) -> 0.4 | J33: =IF(B11<=Расчет!D9+Расчет!D10,0,K33) -> 0.4 | K33: =IF(B11>=Расчет!D9+Расчет!D10+Расчет!D12+Расчет!D13,Расчет!D12+Расчет!D13,B11-(Расчет!D9+Расчет!D10)) -> 0.4 | L33: =IF(K33<=0,0,K33) -> 0.4 | O33: МТЗдоп= | P33: =IFERROR(P30/1.5,"---") -> --- | Q33: А
A34: МТЗдоп= | B34: =B30/1.5 -> 61.335495 | C34: А | O34: МТЗдоп= | P34: =IFERROR(P30/1.5,"---") -> --- | Q34: А
A35: МТЗдоп= | B35: =B30/1.5 -> 61.335495 | C35: А | H35: 3 | I35: =IF(Расчет!D15+Расчет!D16<=0,0,J35) -> 0 | J35: =IF(B11<=Расчет!D9+Расчет!D10+Расчет!D12+Расчет!D13,0,K35) -> 0 | K35: =IF(B11>=Расчет!D9+Расчет!D10+Расчет!D12+Расчет!D13+Расчет!D15+Расчет!D16,Расчет!D15+Расчет!D16,B11-(Расчет!D9+Расчет!D10+Расчет!D12+Расчет!D13)) -> -1.6 | L35: =IF(K35<=0,0,K35) -> 0 | O35: МТЗдоп= | P35: =IFERROR(P30/1.5,"---") -> --- | Q35: А
A36: МТЗдоп= | B36: =B30/1.5 -> 61.335495 | C36: А | O36: МТЗдоп= | P36: =IFERROR(P30/1.5,"---") -> --- | Q36: А
A37: МТЗдоп= | B37: =B30/1.5 -> 61.335495 | C37: А | H37: 4 | I37: =IF(Расчет!D18+Расчет!D19<=0,0,J37) -> 0 | J37: =IF(B11<=Расчет!D9+Расчет!D10+Расчет!D12+Расчет!D13+Расчет!D15+Расчет!D16,0,K37) -> 0 | K37: =IF(B11>=Расчет!D9+Расчет!D10+Расчет!D12+Расчет!D13+Расчет!D15+Расчет!D16+Расчет!D18+Расчет!D19,Расчет!D18+Расчет!D19,B11-(Расчет!D9+Расчет!D10+Расчет!D12+Расчет!D13+Расчет!D15+Расчет!D16)) -> -3.6 | L37: =IF(K37<=0,0,K37) -> 0 | O37: МТЗдоп= | P37: =IFERROR(P30/1.5,"---") -> --- | Q37: А
A38: МТЗдоп= | B38: =B30/1.5 -> 61.335495 | C38: А | H38: }{min | I38: суммар: | J38: =SQRT((SUMSQ(L31*(Расчет!E9+Расчет!E10)+L33*(Расчет!E12+Расчет!E13)+L35*(Расчет!E15+Расчет!E16)+L37*(Расчет!E18+Расчет!E19)))+(SUMSQ(Расчет!F5+L31*(Расчет!F9+Расчет!F10)+L33*(Расчет!F12+Расчет!F13)+L35*(Расчет!F15+Расчет!F16)+L37*(Расчет!F18+Расчет!F19)))) -> 10.333798 | K38: Н | O38: МТЗдоп= | P38: =IFERROR(P30/1.5,"---") -> --- | Q38: А
A39: МТЗдоп= | B39: =B30/1.5 -> 61.335495 | C39: А | J39: =IFERROR(SQRT((SUMSQ(L31*(Расчет!E9+Расчет!E10)+L33*(Расчет!E12+Расчет!E13)+L35*(Расчет!E15+Расчет!E16)+L37*(Расчет!E18+Расчет!E19)))+(SUMSQ(Расчет!F6+L31*(Расчет!F9+Расчет!F10)+L33*(Расчет!F12+Расчет!F13)+L35*(Расчет!F15+Расчет!F16)+L37*(Расчет!F18+Расчет!F19)))),"---") -> --- | K39: А | O39: МТЗдоп= | P39: =IFERROR(P30/1.5,"---") -> --- | Q39: А
A40: МТЗдоп= | B40: =B30/1.5 -> 61.335495 | C40: А | H40: Для четвертой точки | L40: Итог | M40: Проверка | O40: МТЗдоп= | P40: =IFERROR(P30/1.5,"---") -> --- | Q40: А
A41: МТЗдоп= | B41: =B30/1.5 -> 61.335495 | C41: А | M41: =IF(L42+L44+L46+L48=B12,TRUE,FALSE) -> TRUE | O41: МТЗдоп= | P41: =IFERROR(P30/1.5,"---") -> --- | Q41: А
H42: 1 | I42: =IF(Расчет!D9+Расчет!D10>=B12,B12,K42) -> 2 | J42: =IF(Расчет!D9+Расчет!D10=B12,B12,K42) -> 2 | K42: =IF(Расчет!D9+Расчет!D10<B12,Расчет!D9+Расчет!D10,I42) -> 2 | L42: =IF(K42<=0,0,K42) -> 2
A43: Токи 3-х фазного КЗ за тр.: | O43: Токи 3-х фазного КЗ за тр.:
A44: I= | B44: =IFERROR(6300/(SQRT(3)*J118),"---") -> 98.61124 | C44: А | H44: 2 | I44: =IF(Расчет!D12+Расчет!D13<=0,0,J44) -> 1.2 | J44: =IF(B12<=Расчет!D9+Расчет!D10,0,K44) -> 1.2 | K44: =IF(B12>=Расчет!D9+Расчет!D10+Расчет!D12+Расчет!D13,Расчет!D12+Расчет!D13,B12-(Расчет!D9+Расчет!D10)) -> 1.2 | L44: =IF(K44<=0,0,K44) -> 1.2 | O44: I= | P44: =IFERROR(6300/(SQRT(3)*J119),"---") -> --- | Q44: А
A45: МТО | B45: =Расчет!K26 -> 20 | C45: А | O45: МТО | P45: =IF(Расчет!$F$6="---","---",Расчет!$K$26) -> --- | Q45: А
A46: МТО | B46: =Расчет!K26 -> 20 | C46: А | H46: 3 | I46: =IF(Расчет!D15+Расчет!D16<=0,0,J46) -> 0 | J46: =IF(B12<=Расчет!D9+Расчет!D10+Расчет!D12+Расчет!D13,0,K46) -> 0 | K46: =IF(B12>=Расчет!D9+Расчет!D10+Расчет!D12+Расчет!D13+Расчет!D15+Расчет!D16,Расчет!D15+Расчет!D16,B12-(Расчет!D9+Расчет!D10+Расчет!D12+Расчет!D13)) -> -0.8 | L46: =IF(K46<=0,0,K46) -> 0 | O46: МТО | P46: =IF(Расчет!$F$6="---","---",Расчет!$K$26) -> --- | Q46: А
...
